Workbook

Sheet Инструкция
A1: Походный калькулятор меню и закупки
A3: Схема: продукты → рецепты → меню → формульная калькуляция по дням и трапезам → агрегированная раскладка для закупки.
A7: Шаг | B7: Действие | C7: Лист | D7: Кто использует
A8: 1 | B8: Задать M, N, резерв и цели. | C8: Ввод | D8: Организатор
A9: 2 | B9: Проверить продукты, упаковки, цены и единицы. | C9: Продукты | D9: Закупки
A10: 3 | B10: Заполнить рецепты на 1 порцию. | C10: Рецепты | D10: Повара
A11: 4 | B11: Выбрать блюда по дням и трапезам. | C11: Меню | D11: Команда
A12: 5 | B12: Работать по количествам продуктов на день и трапезу. | C12: Калькуляция | D12: Дежурные повара
A13: 6 | B13: Использовать агрегированный список для закупки. | C13: Раскладка | D13: Завхоз
A14: 7 | B14: Проверить калории, БЖУ, вес и бюджет. | C14: Сводка | D14: Организатор
A15: 8 | B15: Предложения вносятся руками; затем расчёт запускается заново. | C15: Меню | D15: Ответственный
A17: Правила модели
A18: • Рецепт задаётся на 1 порцию; вода — отдельный ингредиент в мл. • Порции по умолчанию равны числу участников, но могут быть изменены в меню. • «Калькуляция» и «Раскладка» — формульные листы, их не редактируют. • Резерв применяется к закупке, но не увеличивает плановые калории и БЖУ.

Sheet Ввод
A1: 1. Ввод параметров похода
A3: Параметр | B3: Значение | E3: Что меняется вручную
A4: Участников, чел. | E4: B4:B5 — масштаб похода. B6 — резерв только для закупки. B7:B10 — цели для проверки, а не автоматическая подгонка меню.
A5: Дней, суток
A6: Резерв закупки, %
A7: Целевая энергия, ккал/чел/день
A8: Целевой белок, г/чел/день
A9: Целевой жир, г/чел/день
A10: Целевые углеводы, г/чел/день
A11: Валюта
A12: Сезон | E12: Расчет ккал на лайтовый день без больших нагрузок
A13: Погода / температура | E13: Расчёт БЖУ в пропорции
A14: Предпочтения / ограничения

Sheet Продукты
A1: 2. Справочник продуктов
A3: Жёлтые поля редактируются. Рецепты используют базовые единицы г, мл или шт.; нутриенты указаны на 100 г.
A5: ID | B5: Категория | C5: Продукт | D5: Ед. закупки | E5: Размер упаковки | F5: Базовая ед. | G5: ккал/100 г | H5: Белок/100 г | I5: Жир/100 г | J5: Угл./100 г | K5: Цена/уп., KZT | L5: В закупку? | M5: Примечание
A6: 1 | B6: Крупы/макароны | C6: Овсяные хлопья | D6: пачка | E6: 500 | F6: г | G6: 360 | H6: 12 | I6: 6 | J6: 62 | K6: 650 | L6: Да | M6: Завтрак

Sheet Рецепты
A1: 3. Рецепты: ингредиенты на 1 порцию
A3: Каждый блок — отдельный рецепт. Вода указывается отдельной строкой. Жёлтые ячейки — ручной ввод. | H3: Техническая таблица для формул — не редактировать
P4: Рецепт_ID | Q4: Рецепт
A5: Рецепт_ID | B5: R001 | C5: Щи из свежей капусты | H5: Рецепт_ID | I5: Рецепт | J5: Продукт_ID | K5: Продукт | L5: Кол-во/порцию | M5: Ед. | N5: Примечание | P5: =$B$5 -> R001
A6: Суп на обед, мясной. Готовить в первый день, овощи и зажарку можно подготовить дома накануне выезда. | H6: =$B$5 -> R001 | P6: =$B$26 -> R002
A7: Продукт | B7: Кол-во/порция | C7: Ед. | D7: Примечание | H7: =$B$5 -> R001 | P7: =$B$38 -> R003
A8: Вода техническая | H8: =$B$5 -> R001 | P8: =$B$50 -> R004
A9: Вода питьевая | H9: =$B$5 -> R001 | P9: =$B$62 -> R005
A10: Говядина тушеная | H10: =$B$5 -> R001 | P10: =$B$74 -> R006
A11: Картофель | H11: =$B$5 -> R001 | P11: =$B$86 -> R007
A12: Морковь | H12: =$B$5 -> R001 | P12: =$B$98 -> R008
A13: Лук репчатый | H13: =$B$5 -> R001 | P13: =$B$125 -> R009
A14: Капуста | H14: =$B$5 -> R001 | P14: =$B$137 -> R010
A15: Соль | H15: =$B$5 -> R001
A16: Перец горошком | H16: =$B$5 -> R001
A17: Лавровый лист | H17: =$B$5 -> R001
A18: Чеснок | H18: =$B$5 -> R001
A19: Укроп сухой | H19: =$B$5 -> R001
A20: Петрушка сухая | H20: =$B$5 -> R001
A21: Томатная паста | H21: =$B$5 -> R001
A22: Майонез | H22: =$B$5 -> R001
A23: Кубик магги | H23: =$B$26 -> R002
A24: Масло растительное | H24: =$B$26 -> R002
H25: =$B$26 -> R002
A26: Рецепт_ID | B26: R002 | C26: Закуска №1 | H26: =$B$26 -> R002
A27: К щам. | H27: =$B$26 -> R002
A28: Продукт | B28: Кол-во/порция | C28: Ед. | D28: Примечание | H28: =$B$26 -> R002
A29: Хлеб черный | H29: =$B$38 -> R003
A30: Сало | H30: =$B$38 -> R003
A31: Сыр твёрдый | H31: =$B$38 -> R003
A32: Помидор | H32: =$B$38 -> R003
A33: Огурец | H33: =$B$38 -> R003
A34: Лук зеленый | H34: =$B$38 -> R003
H35: =$B$38 -> R003
H36: =$B$38 -> R003
H37: =$B$38 -> R003
A38: Рецепт_ID | B38: R003 | C38: Чай с сахаром | H38: =$B$38 -> R003
A39: Чай как чай. | H39: =$B$62 -> R005
A40: Продукт | B40: Кол-во/порция | C40: Ед. | D40: Примечание | H40: =$B$62 -> R005
A41: Чай | H41: =$B$62 -> R005
...

Sheet Меню
A1: 4. Меню по дням и трапезам
A3: Заполните или измените меню руками. Порции по умолчанию равны числу участников; при необходимости замените значение.
A5: День | B5: Трапеза | C5: Блюдо | D5: Рецепт_ID | E5: Порций | F5: Комментарий / предпочтения
A6: 1
A7: 1
A8: 1
A9: 1
A10: 1
A11: 1
A12: 2
A13: 2
A14: 2
A15: 2
A16: 2
A17: 2
D90: =IFERROR(INDEX(Рецепты!$P$5:$P$14,MATCH($C90,Рецепты!$Q$5:$Q$14,0)),"") | E90: =IF($C90="","",Ввод!$B$4)
D91: =IFERROR(INDEX(Рецепты!$P$5:$P$14,MATCH($C91,Рецепты!$Q$5:$Q$14,0)),"") | E91: =IF($C91="","",Ввод!$B$4)
D92: =IFERROR(INDEX(Рецепты!$P$5:$P$14,MATCH($C92,Рецепты!$Q$5:$Q$14,0)),"") | E92: =IF($C92="","",Ввод!$B$4)
D93: =IFERROR(INDEX(Рецепты!$P$5:$P$14,MATCH($C93,Рецепты!$Q$5:$Q$14,0)),"") | E93: =IF($C93="","",Ввод!$B$4)
D94: =IFERROR(INDEX(Рецепты!$P$5:$P$14,MATCH($C94,Рецепты!$Q$5:$Q$14,0)),"") | E94: =IF($C94="","",Ввод!$B$4)
D95: =IFERROR(INDEX(Рецепты!$P$5:$P$14,MATCH($C95,Рецепты!$Q$5:$Q$14,0)),"") | E95: =IF($C95="","",Ввод!$B$4)

Sheet Калькуляция
A1: 5. Калькуляция подготовки по дням и трапезам
A3: Формульный рабочий лист: одна строка — один ингредиент одного блюда. Данные берутся из «Меню» и «Рецепты»; здесь ничего менять не нужно.
A5: День | B5: Трапеза | C5: Блюдо | D5: Рецепт_ID | E5: Продукт_ID | F5: Продукт | G5: Ед. | H5: Кол-во/порцию | I5: Порций | J5: Всего | K5: ккал | L5: Белок, г | M5: Жир, г | N5: Угл., г | O5: Примечание
A6: =IF($E6="","",Меню!$A$6) | B6: =IF($E6="","",Меню!$B$6) | C6: =IF($E6="","",Меню!$C$6) | D6: =IF($E6="","",Меню!$D$6) | E6: =IFERROR(IF(IFERROR(INDEX(Рецепты!$H$6:$H$85,MATCH(Меню!$D$6,Рецепты!$H$6:$H$85,0)+0)=Меню!$D$6,FALSE),INDEX(Рецепты!$J$6:$J$85,MATCH(Меню!$D$6,Рецепты!$H$6:$H$85,0)+0),""),"") | F6: =IF($E6="","",INDEX(Рецепты!$K$6:$K$85,MATCH(Меню!$D$6,Рецепты!$H$6:$H$85,0)+0)) | G6: =IF($E6="","",INDEX(Рецепты!$M$6:$M$85,MATCH(Меню!$D$6,Рецепты!$H$6:$H$85,0)+0)) | H6: =IFERROR(IF(IFERROR(INDEX(Рецепты!$H$6:$H$85,MATCH(Меню!$D$6,Рецепты!$H$6:$H$85,0)+0)=Меню!$D$6,FALSE),INDEX(Рецепты!$L$6:$L$85,MATCH(Меню!$D$6,Рецепты!$H$6:$H$85,0)+0),0),0) -> 0 | I6: =IF($F6="","",Меню!$E$6) | J6: =IFERROR($H6*$I6,0) -> 0 | K6: =IFERROR($J6/100*INDEX(Продукты!$G$6:$G$66,MATCH($E6,Продукты!$A$6:$A$66,0)),0) -> 0 | L6: =IFERROR($J6/100*INDEX(Продукты!$H$6:$H$66,MATCH($E6,Продукты!$A$6:$A$66,0)),0) -> 0 | M6: =IFERROR($J6/100*INDEX(Продукты!$I$6:$I$66,MATCH($E6,Продукты!$A$6:$A$66,0)),0) -> 0 | N6: =IFERROR($J6/100*INDEX(Продукты!$J$6:$J$66,MATCH($E6,Продукты!$A$6:$A$66,0)),0) -> 0 | O6: =IFERROR(IF(IFERROR(INDEX(Рецепты!$H$6:$H$85,MATCH(Меню!$D$6,Рецепты!$H$6:$H$85,0)+0)=Меню!$D$6,FALSE),INDEX(Рецепты!$N$6:$N$85,MATCH(Меню!$D$6,Рецепты!$H$6:$H$85,0)+0),""),"")
A7: =IF($E7="","",Меню!$A$6) | B7: =IF($E7="","",Меню!$B$6) | C7: =IF($E7="","",Меню!$C$6) | D7: =IF($E7="","",Меню!$D$6) | E7: =IFERROR(IF(IFERROR(INDEX(Рецепты!$H$6:$H$85,MATCH(Меню!$D$6,Рецепты!$H$6:$H$85,0)+1)=Меню!$D$6,FALSE),INDEX(Рецепты!$J$6:$J$85,MATCH(Меню!$D$6,Рецепты!$H$6:$H$85,0)+1),""),"") | F7: =IF($E7="","",INDEX(Рецепты!$K$6:$K$85,MATCH(Меню!$D$6,Рецепты!$H$6:$H$85,0)+1)) | G7: =IF($E7="","",INDEX(Рецепты!$M$6:$M$85,MATCH(Меню!$D$6,Рецепты!$H$6:$H$85,0)+1)) | H7: =IFERROR(IF(IFERROR(INDEX(Рецепты!$H$6:$H$85,MATCH(Меню!$D$6,Рецепты!$H$6:$H$85,0)+1)=Меню!$D$6,FALSE),INDEX(Рецепты!$L$6:$L$85,MATCH(Меню!$D$6,Рецепты!$H$6:$H$85,0)+1),0),0) -> 0 | I7: =IF($F7="","",Меню!$E$6) | J7: =IFERROR($H7*$I7,0) -> 0 | K7: =IFERROR($J7/100*INDEX(Продукты!$G$6:$G$66,MATCH($E7,Продукты!$A$6:$A$66,0)),0) -> 0 | L7: =IFERROR($J7/100*INDEX(Продукты!$H$6:$H$66,MATCH($E7,Продукты!$A$6:$A$66,0)),0) -> 0 | M7: =IFERROR($J7/100*INDEX(Продукты!$I$6:$I$66,MATCH($E7,Продукты!$A$6:$A$66,0)),0) -> 0 | N7: =IFERROR($J7/100*INDEX(Продукты!$J$6:$J$66,MATCH($E7,Продукты!$A$6:$A$66,0)),0) -> 0 | O7: =IFERROR(IF(IFERROR(INDEX(Рецепты!$H$6:$H$85,MATCH(Меню!$D$6,Рецепты!$H$6:$H$85,0)+1)=Меню!$D$6,FALSE),INDEX(Рецепты!$N$6:$N$85,MATCH(Меню!$D$6,Рецепты!$H$6:$H$85,0)+1),""),"")
A8: =IF($E8="","",Меню!$A$6) | B8: =IF($E8="","",Меню!$B$6) | C8: =IF($E8="","",Меню!$C$6) | D8: =IF($E8="","",Меню!$D$6) | E8: =IFERROR(IF(IFERROR(INDEX(Рецепты!$H$6:$H$85,MATCH(Меню!$D$6,Рецепты!$H$6:$H$85,0)+2)=Меню!$D$6,FALSE),INDEX(Рецепты!$J$6:$J$85,MATCH(Меню!$D$6,Рецепты!$H$6:$H$85,0)+2),""),"") | F8: =IF($E8="","",INDEX(Рецепты!$K$6:$K$85,MATCH(Меню!$D$6,Рецепты!$H$6:$H$85,0)+2)) | G8: =IF($E8="","",INDEX(Рецепты!$M$6:$M$85,MATCH(Меню!$D$6,Рецепты!$H$6:$H$85,0)+2)) | H8: =IFERROR(IF(IFERROR(INDEX(Рецепты!$H$6:$H$85,MATCH(Меню!$D$6,Рецепты!$H$6:$H$85,0)+2)=Меню!$D$6,FALSE),INDEX(Рецепты!$L$6:$L$85,MATCH(Меню!$D$6,Рецепты!$H$6:$H$85,0)+2),0),0) -> 0 | I8: =IF($F8="","",Меню!$E$6) | J8: =IFERROR($H8*$I8,0) -> 0 | K8: =IFERROR($J8/100*INDEX(Продукты!$G$6:$G$66,MATCH($E8,Продукты!$A$6:$A$66,0)),0) -> 0 | L8: =IFERROR($J8/100*INDEX(Продукты!$H$6:$H$66,MATCH($E8,Продукты!$A$6:$A$66,0)),0) -> 0 | M8: =IFERROR($J8/100*INDEX(Продукты!$I$6:$I$66,MATCH($E8,Продукты!$A$6:$A$66,0)),0) -> 0 | N8: =IFERROR($J8/100*INDEX(Продукты!$J$6:$J$66,MATCH($E8,Продукты!$A$6:$A$66,0)),0) -> 0 | O8: =IFERROR(IF(IFERROR(INDEX(Рецепты!$H$6:$H$85,MATCH(Меню!$D$6,Рецепты!$H$6:$H$85,0)+2)=Меню!$D$6,FALSE),INDEX(Рецепты!$N$6:$N$85,MATCH(Меню!$D$6,Рецепты!$H$6:$H$85,0)+2),""),"")
A9: =IF($E9="","",Меню!$A$6) | B9: =IF($E9="","",Меню!$B$6) | C9: =IF($E9="","",Меню!$C$6) | D9: =IF($E9="","",Меню!$D$6) | E9: =IFERROR(IF(IFERROR(INDEX(Рецепты!$H$6:$H$85,MATCH(Меню!$D$6,Рецепты!$H$6:$H$85,0)+3)=Меню!$D$6,FALSE),INDEX(Рецепты!$J$6:$J$85,MATCH(Меню!$D$6,Рецепты!$H$6:$H$85,0)+3),""),"") | F9: =IF($E9="","",INDEX(Рецепты!$K$6:$K$85,MATCH(Меню!$D$6,Рецепты!$H$6:$H$85,0)+3)) | G9: =IF($E9="","",INDEX(Рецепты!$M$6:$M$85,MATCH(Меню!$D$6,Рецепты!$H$6:$H$85,0)+3)) | H9: =IFERROR(IF(IFERROR(INDEX(Рецепты!$H$6:$H$85,MATCH(Меню!$D$6,Рецепты!$H$6:$H$85,0)+3)=Меню!$D$6,FALSE),INDEX(Рецепты!$L$6:$L$85,MATCH(Меню!$D$6,Рецепты!$H$6:$H$85,0)+3),0),0) -> 0 | I9: =IF($F9="","",Меню!$E$6) | J9: =IFERROR($H9*$I9,0) -> 0 | K9: =IFERROR($J9/100*INDEX(Продукты!$G$6:$G$66,MATCH($E9,Продукты!$A$6:$A$66,0)),0) -> 0 | L9: =IFERROR($J9/100*INDEX(Продукты!$H$6:$H$66,MATCH($E9,Продукты!$A$6:$A$66,0)),0) -> 0 | M9: =IFERROR($J9/100*INDEX(Продукты!$I$6:$I$66,MATCH($E9,Продукты!$A$6:$A$66,0)),0) -> 0 | N9: =IFERROR($J9/100*INDEX(Продукты!$J$6:$J$66,MATCH($E9,Продукты!$A$6:$A$66,0)),0) -> 0 | O9: =IFERROR(IF(IFERROR(INDEX(Рецепты!$H$6:$H$85,MATCH(Меню!$D$6,Рецепты!$H$6:$H$85,0)+3)=Меню!$D$6,FALSE),INDEX(Рецепты!$N$6:$N$85,MATCH(Меню!$D$6,Рецепты!$H$6:$H$85,0)+3),""),"")
A10: =IF($E10="","",Меню!$A$6) | B10: =IF($E10="","",Меню!$B$6) | C10: =IF($E10="","",Меню!$C$6) | D10: =IF($E10="","",Меню!$D$6) | E10: =IFERROR(IF(IFERROR(INDEX(Рецепты!$H$6:$H$85,MATCH(Меню!$D$6,Рецепты!$H$6:$H$85,0)+4)=Меню!$D$6,FALSE),INDEX(Рецепты!$J$6:$J$85,MATCH(Меню!$D$6,Рецепты!$H$6:$H$85,0)+4),""),"") | F10: =IF($E10="","",INDEX(Рецепты!$K$6:$K$85,MATCH(Меню!$D$6,Рецепты!$H$6:$H$85,0)+4)) | G10: =IF($E10="","",INDEX(Рецепты!$M$6:$M$85,MATCH(Меню!$D$6,Рецепты!$H$6:$H$85,0)+4)) | H10: =IFERROR(IF(IFERROR(INDEX(Рецепты!$H$6:$H$85,MATCH(Меню!$D$6,Рецепты!$H$6:$H$85,0)+4)=Меню!$D$6,FALSE),INDEX(Рецепты!$L$6:$L$85,MATCH(Меню!$D$6,Рецепты!$H$6:$H$85,0)+4),0),0) -> 0 | I10: =IF($F10="","",Меню!$E$6) | J10: =IFERROR($H10*$I10,0) -> 0 | K10: =IFERROR($J10/100*INDEX(Продукты!$G$6:$G$66,MATCH($E10,Продукты!$A$6:$A$66,0)),0) -> 0 | L10: =IFERROR($J10/100*INDEX(Продукты!$H$6:$H$66,MATCH($E10,Продукты!$A$6:$A$66,0)),0) -> 0 | M10: =IFERROR($J10/100*INDEX(Продукты!$I$6:$I$66,MATCH($E10,Продукты!$A$6:$A$66,0)),0) -> 0 | N10: =IFERROR($J10/100*INDEX(Продукты!$J$6:$J$66,MATCH($E10,Продукты!$A$6:$A$66,0)),0) -> 0 | O10: =IFERROR(IF(IFERROR(INDEX(Рецепты!$H$6:$H$85,MATCH(Меню!$D$6,Рецепты!$H$6:$H$85,0)+4)=Меню!$D$6,FALSE),INDEX(Рецепты!$N$6:$N$85,MATCH(Меню!$D$6,Рецепты!$H$6:$H$85,0)+4),""),"")
A11: =IF($E11="","",Меню!$A$6) | B11: =IF($E11="","",Меню!$B$6) | C11: =IF($E11="","",Меню!$C$6) | D11: =IF($E11="","",Меню!$D$6) | E11: =IFERROR(IF(IFERROR(INDEX(Рецепты!$H$6:$H$85,MATCH(Меню!$D$6,Рецепты!$H$6:$H$85,0)+5)=Меню!$D$6,FALSE),INDEX(Рецепты!$J$6:$J$85,MATCH(Меню!$D$6,Рецепты!$H$6:$H$85,0)+5),""),"") | F11: =IF($E11="","",INDEX(Рецепты!$K$6:$K$85,MATCH(Меню!$D$6,Рецепты!$H$6:$H$85,0)+5)) | G11: =IF($E11="","",INDEX(Рецепты!$M$6:$M$85,MATCH(Меню!$D$6,Рецепты!$H$6:$H$85,0)+5)) | H11: =IFERROR(IF(IFERROR(INDEX(Рецепты!$H$6:$H$85,MATCH(Меню!$D$6,Рецепты!$H$6:$H$85,0)+5)=Меню!$D$6,FALSE),INDEX(Рецепты!$L$6:$L$85,MATCH(Меню!$D$6,Рецепты!$H$6:$H$85,0)+5),0),0) -> 0 | I11: =IF($F11="","",Меню!$E$6) | J11: =IFERROR($H11*$I11,0) -> 0 | K11: =IFERROR($J11/100*INDEX(Продукты!$G$6:$G$66,MATCH($E11,Продукты!$A$6:$A$66,0)),0) -> 0 | L11: =IFERROR($J11/100*INDEX(Продукты!$H$6:$H$66,MATCH($E11,Продукты!$A$6:$A$66,0)),0) -> 0 | M11: =IFERROR($J11/100*INDEX(Продукты!$I$6:$I$66,MATCH($E11,Продукты!$A$6:$A$66,0)),0) -> 0 | N11: =IFERROR($J11/100*INDEX(Продукты!$J$6:$J$66,MATCH($E11,Продукты!$A$6:$A$66,0)),0) -> 0 | O11: =IFERROR(IF(IFERROR(INDEX(Рецепты!$H$6:$H$85,MATCH(Меню!$D$6,Рецепты!$H$6:$H$85,0)+5)=Меню!$D$6,FALSE),INDEX(Рецепты!$N$6:$N$85,MATCH(Меню!$D$6,Рецепты!$H$6:$H$85,0)+5),""),"")
A12: =IF($E12="","",Меню!$A$6) | B12: =IF($E12="","",Меню!$B$6) | C12: =IF($E12="","",Меню!$C$6) | D12: =IF($E12="","",Меню!$D$6) | E12: =IFERROR(IF(IFERROR(INDEX(Рецепты!$H$6:$H$85,MATCH(Меню!$D$6,Рецепты!$H$6:$H$85,0)+6)=Меню!$D$6,FALSE),INDEX(Рецепты!$J$6:$J$85,MATCH(Меню!$D$6,Рецепты!$H$6:$H$85,0)+6),""),"") | F12: =IF($E12="","",INDEX(Рецепты!$K$6:$K$85,MATCH(Меню!$D$6,Рецепты!$H$6:$H$85,0)+6)) | G12: =IF($E12="","",INDEX(Рецепты!$M$6:$M$85,MATCH(Меню!$D$6,Рецепты!$H$6:$H$85,0)+6)) | H12: =IFERROR(IF(IFERROR(INDEX(Рецепты!$H$6:$H$85,MATCH(Меню!$D$6,Рецепты!$H$6:$H$85,0)+6)=Меню!$D$6,FALSE),INDEX(Рецепты!$L$6:$L$85,MATCH(Меню!$D$6,Рецепты!$H$6:$H$85,0)+6),0),0) -> 0 | I12: =IF($F12="","",Меню!$E$6) | J12: =IFERROR($H12*$I12,0) -> 0 | K12: =IFERROR($J12/100*INDEX(Продукты!$G$6:$G$66,MATCH($E12,Продукты!$A$6:$A$66,0)),0) -> 0 | L12: =IFERROR($J12/100*INDEX(Продукты!$H$6:$H$66,MATCH($E12,Продукты!$A$6:$A$66,0)),0) -> 0 | M12: =IFERROR($J12/100*INDEX(Продукты!$I$6:$I$66,MATCH($E12,Продукты!$A$6:$A$66,0)),0) -> 0 | N12: =IFERROR($J12/100*INDEX(Продукты!$J$6:$J$66,MATCH($E12,Продукты!$A$6:$A$66,0)),0) -> 0 | O12: =IFERROR(IF(IFERROR(INDEX(Рецепты!$H$6:$H$85,MATCH(Меню!$D$6,Рецепты!$H$6:$H$85,0)+6)=Меню!$D$6,FALSE),INDEX(Рецепты!$N$6:$N$85,MATCH(Меню!$D$6,Рецепты!$H$6:$H$85,0)+6),""),"")
A13: =IF($E13="","",Меню!$A$6) | B13: =IF($E13="","",Меню!$B$6) | C13: =IF($E13="","",Меню!$C$6) | D13: =IF($E13="","",Меню!$D$6) | E13: =IFERROR(IF(IFERROR(INDEX(Рецепты!$H$6:$H$85,MATCH(Меню!$D$6,Рецепты!$H$6:$H$85,0)+7)=Меню!$D$6,FALSE),INDEX(Рецепты!$J$6:$J$85,MATCH(Меню!$D$6,Рецепты!$H$6:$H$85,0)+7),""),"") | F13: =IF($E13="","",INDEX(Рецепты!$K$6:$K$85,MATCH(Меню!$D$6,Рецепты!$H$6:$H$85,0)+7)) | G13: =IF($E13="","",INDEX(Рецепты!$M$6:$M$85,MATCH(Меню!$D$6,Рецепты!$H$6:$H$85,0)+7)) | H13: =IFERROR(IF(IFERROR(INDEX(Рецепты!$H$6:$H$85,MATCH(Меню!$D$6,Рецепты!$H$6:$H$85,0)+7)=Меню!$D$6,FALSE),INDEX(Рецепты!$L$6:$L$85,MATCH(Меню!$D$6,Рецепты!$H$6:$H$85,0)+7),0),0) -> 0 | I13: =IF($F13="","",Меню!$E$6) | J13: =IFERROR($H13*$I13,0) -> 0 | K13: =IFERROR($J13/100*INDEX(Продукты!$G$6:$G$66,MATCH($E13,Продукты!$A$6:$A$66,0)),0) -> 0 | L13: =IFERROR($J13/100*INDEX(Продукты!$H$6:$H$66,MATCH($E13,Продукты!$A$6:$A$66,0)),0) -> 0 | M13: =IFERROR($J13/100*INDEX(Продукты!$I$6:$I$66,MATCH($E13,Продукты!$A$6:$A$66,0)),0) -> 0 | N13: =IFERROR($J13/100*INDEX(Продукты!$J$6:$J$66,MATCH($E13,Продукты!$A$6:$A$66,0)),0) -> 0 | O13: =IFERROR(IF(IFERROR(INDEX(Рецепты!$H$6:$H$85,MATCH(Меню!$D$6,Рецепты!$H$6:$H$85,0)+7)=Меню!$D$6,FALSE),INDEX(Рецепты!$N$6:$N$85,MATCH(Меню!$D$6,Рецепты!$H$6:$H$85,0)+7),""),"")
A14: =IF($E14="","",Меню!$A$6) | B14: =IF($E14="","",Меню!$B$6) | C14: =IF($E14="","",Меню!$C$6) | D14: =IF($E14="","",Меню!$D$6) | E14: =IFERROR(IF(IFERROR(INDEX(Рецепты!$H$6:$H$85,MATCH(Меню!$D$6,Рецепты!$H$6:$H$85,0)+8)=Меню!$D$6,FALSE),INDEX(Рецепты!$J$6:$J$85,MATCH(Меню!$D$6,Рецепты!$H$6:$H$85,0)+8),""),"") | F14: =IF($E14="","",INDEX(Рецепты!$K$6:$K$85,MATCH(Меню!$D$6,Рецепты!$H$6:$H$85,0)+8)) | G14: =IF($E14="","",INDEX(Рецепты!$M$6:$M$85,MATCH(Меню!$D$6,Рецепты!$H$6:$H$85,0)+8)) | H14: =IFERROR(IF(IFERROR(INDEX(Рецепты!$H$6:$H$85,MATCH(Меню!$D$6,Рецепты!$H$6:$H$85,0)+8)=Меню!$D$6,FALSE),INDEX(Рецепты!$L$6:$L$85,MATCH(Меню!$D$6,Рецепты!$H$6:$H$85,0)+8),0),0) -> 0 | I14: =IF($F14="","",Меню!$E$6) | J14: =IFERROR($H14*$I14,0) -> 0 | K14: =IFERROR($J14/100*INDEX(Продукты!$G$6:$G$66,MATCH($E14,Продукты!$A$6:$A$66,0)),0) -> 0 | L14: =IFERROR($J14/100*INDEX(Продукты!$H$6:$H$66,MATCH($E14,Продукты!$A$6:$A$66,0)),0) -> 0 | M14: =IFERROR($J14/100*INDEX(Продукты!$I$6:$I$66,MATCH($E14,Продукты!$A$6:$A$66,0)),0) -> 0 | N14: =IFERROR($J14/100*INDEX(Продукты!$J$6:$J$66,MATCH($E14,Продукты!$A$6:$A$66,0)),0) -> 0 | O14: =IFERROR(IF(IFERROR(INDEX(Рецепты!$H$6:$H$85,MATCH(Меню!$D$6,Рецепты!$H$6:$H$85,0)+8)=Меню!$D$6,FALSE),INDEX(Рецепты!$N$6:$N$85,MATCH(Меню!$D$6,Рецепты!$H$6:$H$85,0)+8),""),"")
A15: =IF($E15="","",Меню!$A$6) | B15: =IF($E15="","",Меню!$B$6) | C15: =IF($E15="","",Меню!$C$6) | D15: =IF($E15="","",Меню!$D$6) | E15: =IFERROR(IF(IFERROR(INDEX(Рецепты!$H$6:$H$85,MATCH(Меню!$D$6,Рецепты!$H$6:$H$85,0)+9)=Меню!$D$6,FALSE),INDEX(Рецепты!$J$6:$J$85,MATCH(Меню!$D$6,Рецепты!$H$6:$H$85,0)+9),""),"") | F15: =IF($E15="","",INDEX(Рецепты!$K$6:$K$85,MATCH(Меню!$D$6,Рецепты!$H$6:$H$85,0)+9)) | G15: =IF($E15="","",INDEX(Рецепты!$M$6:$M$85,MATCH(Меню!$D$6,Рецепты!$H$6:$H$85,0)+9)) | H15: =IFERROR(IF(IFERROR(INDEX(Рецепты!$H$6:$H$85,MATCH(Меню!$D$6,Рецепты!$H$6:$H$85,0)+9)=Меню!$D$6,FALSE),INDEX(Рецепты!$L$6:$L$85,MATCH(Меню!$D$6,Рецепты!$H$6:$H$85,0)+9),0),0) -> 0 | I15: =IF($F15="","",Меню!$E$6) | J15: =IFERROR($H15*$I15,0) -> 0 | K15: =IFERROR($J15/100*INDEX(Продукты!$G$6:$G$66,MATCH($E15,Продукты!$A$6:$A$66,0)),0) -> 0 | L15: =IFERROR($J15/100*INDEX(Продукты!$H$6:$H$66,MATCH($E15,Продукты!$A$6:$A$66,0)),0) -> 0 | M15: =IFERROR($J15/100*INDEX(Продукты!$I$6:$I$66,MATCH($E15,Продукты!$A$6:$A$66,0)),0) -> 0 | N15: =IFERROR($J15/100*INDEX(Продукты!$J$6:$J$66,MATCH($E15,Продукты!$A$6:$A$66,0)),0) -> 0 | O15: =IFERROR(IF(IFERROR(INDEX(Рецепты!$H$6:$H$85,MATCH(Меню!$D$6,Рецепты!$H$6:$H$85,0)+9)=Меню!$D$6,FALSE),INDEX(Рецепты!$N$6:$N$85,MATCH(Меню!$D$6,Рецепты!$H$6:$H$85,0)+9),""),"")
A16: =IF($E16="","",Меню!$A$6) | B16: =IF($E16="","",Меню!$B$6) | C16: =IF($E16="","",Меню!$C$6) | D16: =IF($E16="","",Меню!$D$6) | E16: =IFERROR(IF(IFERROR(INDEX(Рецепты!$H$6:$H$85,MATCH(Меню!$D$6,Рецепты!$H$6:$H$85,0)+10)=Меню!$D$6,FALSE),INDEX(Рецепты!$J$6:$J$85,MATCH(Меню!$D$6,Рецепты!$H$6:$H$85,0)+10),""),"") | F16: =IF($E16="","",INDEX(Рецепты!$K$6:$K$85,MATCH(Меню!$D$6,Рецепты!$H$6:$H$85,0)+10)) | G16: =IF($E16="","",INDEX(Рецепты!$M$6:$M$85,MATCH(Меню!$D$6,Рецепты!$H$6:$H$85,0)+10)) | H16: =IFERROR(IF(IFERROR(INDEX(Рецепты!$H$6:$H$85,MATCH(Меню!$D$6,Рецепты!$H$6:$H$85,0)+10)=Меню!$D$6,FALSE),INDEX(Рецепты!$L$6:$L$85,MATCH(Меню!$D$6,Рецепты!$H$6:$H$85,0)+10),0),0) -> 0 | I16: =IF($F16="","",Меню!$E$6) | J16: =IFERROR($H16*$I16,0) -> 0 | K16: =IFERROR($J16/100*INDEX(Продукты!$G$6:$G$66,MATCH($E16,Продукты!$A$6:$A$66,0)),0) -> 0 | L16: =IFERROR($J16/100*INDEX(Продукты!$H$6:$H$66,MATCH($E16,Продукты!$A$6:$A$66,0)),0) -> 0 | M16: =IFERROR($J16/100*INDEX(Продукты!$I$6:$I$66,MATCH($E16,Продукты!$A$6:$A$66,0)),0) -> 0 | N16: =IFERROR($J16/100*INDEX(Продукты!$J$6:$J$66,MATCH($E16,Продукты!$A$6:$A$66,0)),0) -> 0 | O16: =IFERROR(IF(IFERROR(INDEX(Рецепты!$H$6:$H$85,MATCH(Меню!$D$6,Рецепты!$H$6:$H$85,0)+10)=Меню!$D$6,FALSE),INDEX(Рецепты!$N$6:$N$85,MATCH(Меню!$D$6,Рецепты!$H$6:$H$85,0)+10),""),"")
A17: =IF($E17="","",Меню!$A$6) | B17: =IF($E17="","",Меню!$B$6) | C17: =IF($E17="","",Меню!$C$6) | D17: =IF($E17="","",Меню!$D$6) | E17: =IFERROR(IF(IFERROR(INDEX(Рецепты!$H$6:$H$85,MATCH(Меню!$D$6,Рецепты!$H$6:$H$85,0)+11)=Меню!$D$6,FALSE),INDEX(Рецепты!$J$6:$J$85,MATCH(Меню!$D$6,Рецепты!$H$6:$H$85,0)+11),""),"") | F17: =IF($E17="","",INDEX(Рецепты!$K$6:$K$85,MATCH(Меню!$D$6,Рецепты!$H$6:$H$85,0)+11)) | G17: =IF($E17="","",INDEX(Рецепты!$M$6:$M$85,MATCH(Меню!$D$6,Рецепты!$H$6:$H$85,0)+11)) | H17: =IFERROR(IF(IFERROR(INDEX(Рецепты!$H$6:$H$85,MATCH(Меню!$D$6,Рецепты!$H$6:$H$85,0)+11)=Меню!$D$6,FALSE),INDEX(Рецепты!$L$6:$L$85,MATCH(Меню!$D$6,Рецепты!$H$6:$H$85,0)+11),0),0) -> 0 | I17: =IF($F17="","",Меню!$E$6) | J17: =IFERROR($H17*$I17,0) -> 0 | K17: =IFERROR($J17/100*INDEX(Продукты!$G$6:$G$66,MATCH($E17,Продукты!$A$6:$A$66,0)),0) -> 0 | L17: =IFERROR($J17/100*INDEX(Продукты!$H$6:$H$66,MATCH($E17,Продукты!$A$6:$A$66,0)),0) -> 0 | M17: =IFERROR($J17/100*INDEX(Продукты!$I$6:$I$66,MATCH($E17,Продукты!$A$6:$A$66,0)),0) -> 0 | N17: =IFERROR($J17/100*INDEX(Продукты!$J$6:$J$66,MATCH($E17,Продукты!$A$6:$A$66,0)),0) -> 0 | O17: =IFERROR(IF(IFERROR(INDEX(Рецепты!$H$6:$H$85,MATCH(Меню!$D$6,Рецепты!$H$6:$H$85,0)+11)=Меню!$D$6,FALSE),INDEX(Рецепты!$N$6:$N$85,MATCH(Меню!$D$6,Рецепты!$H$6:$H$85,0)+11),""),"")
A18: =IF($E18="","",Меню!$A$6) | B18: =IF($E18="","",Меню!$B$6) | C18: =IF($E18="","",Меню!$C$6) | D18: =IF($E18="","",Меню!$D$6) | E18: =IFERROR(IF(IFERROR(INDEX(Рецепты!$H$6:$H$85,MATCH(Меню!$D$6,Рецепты!$H$6:$H$85,0)+12)=Меню!$D$6,FALSE),INDEX(Рецепты!$J$6:$J$85,MATCH(Меню!$D$6,Рецепты!$H$6:$H$85,0)+12),""),"") | F18: =IF($E18="","",INDEX(Рецепты!$K$6:$K$85,MATCH(Меню!$D$6,Рецепты!$H$6:$H$85,0)+12)) | G18: =IF($E18="","",INDEX(Рецепты!$M$6:$M$85,MATCH(Меню!$D$6,Рецепты!$H$6:$H$85,0)+12)) | H18: =IFERROR(IF(IFERROR(INDEX(Рецепты!$H$6:$H$85,MATCH(Меню!$D$6,Рецепты!$H$6:$H$85,0)+12)=Меню!$D$6,FALSE),INDEX(Рецепты!$L$6:$L$85,MATCH(Меню!$D$6,Рецепты!$H$6:$H$85,0)+12),0),0) -> 0 | I18: =IF($F18="","",Меню!$E$6) | J18: =IFERROR($H18*$I18,0) -> 0 | K18: =IFERROR($J18/100*INDEX(Продукты!$G$6:$G$66,MATCH($E18,Продукты!$A$6:$A$66,0)),0) -> 0 | L18: =IFERROR($J18/100*INDEX(Продукты!$H$6:$H$66,MATCH($E18,Продукты!$A$6:$A$66,0)),0) -> 0 | M18: =IFERROR($J18/100*INDEX(Продукты!$I$6:$I$66,MATCH($E18,Продукты!$A$6:$A$66,0)),0) -> 0 | N18: =IFERROR($J18/100*INDEX(Продукты!$J$6:$J$66,MATCH($E18,Продукты!$A$6:$A$66,0)),0) -> 0 | O18: =IFERROR(IF(IFERROR(INDEX(Рецепты!$H$6:$H$85,MATCH(Меню!$D$6,Рецепты!$H$6:$H$85,0)+12)=Меню!$D$6,FALSE),INDEX(Рецепты!$N$6:$N$85,MATCH(Меню!$D$6,Рецепты!$H$6:$H$85,0)+12),""),"")
A19: =IF($E19="","",Меню!$A$6) | B19: =IF($E19="","",Меню!$B$6) | C19: =IF($E19="","",Меню!$C$6) | D19: =IF($E19="","",Меню!$D$6) | E19: =IFERROR(IF(IFERROR(INDEX(Рецепты!$H$6:$H$85,MATCH(Меню!$D$6,Рецепты!$H$6:$H$85,0)+13)=Меню!$D$6,FALSE),INDEX(Рецепты!$J$6:$J$85,MATCH(Меню!$D$6,Рецепты!$H$6:$H$85,0)+13),""),"") | F19: =IF($E19="","",INDEX(Рецепты!$K$6:$K$85,MATCH(Меню!$D$6,Рецепты!$H$6:$H$85,0)+13)) | G19: =IF($E19="","",INDEX(Рецепты!$M$6:$M$85,MATCH(Меню!$D$6,Рецепты!$H$6:$H$85,0)+13)) | H19: =IFERROR(IF(IFERROR(INDEX(Рецепты!$H$6:$H$85,MATCH(Меню!$D$6,Рецепты!$H$6:$H$85,0)+13)=Меню!$D$6,FALSE),INDEX(Рецепты!$L$6:$L$85,MATCH(Меню!$D$6,Рецепты!$H$6:$H$85,0)+13),0),0) -> 0 | I19: =IF($F19="","",Меню!$E$6) | J19: =IFERROR($H19*$I19,0) -> 0 | K19: =IFERROR($J19/100*INDEX(Продукты!$G$6:$G$66,MATCH($E19,Продукты!$A$6:$A$66,0)),0) -> 0 | L19: =IFERROR($J19/100*INDEX(Продукты!$H$6:$H$66,MATCH($E19,Продукты!$A$6:$A$66,0)),0) -> 0 | M19: =IFERROR($J19/100*INDEX(Продукты!$I$6:$I$66,MATCH($E19,Продукты!$A$6:$A$66,0)),0) -> 0 | N19: =IFERROR($J19/100*INDEX(Продукты!$J$6:$J$66,MATCH($E19,Продукты!$A$6:$A$66,0)),0) -> 0 | O19: =IFERROR(IF(IFERROR(INDEX(Рецепты!$H$6:$H$85,MATCH(Меню!$D$6,Рецепты!$H$6:$H$85,0)+13)=Меню!$D$6,FALSE),INDEX(Рецепты!$N$6:$N$85,MATCH(Меню!$D$6,Рецепты!$H$6:$H$85,0)+13),""),"")
A20: =IF($E20="","",Меню!$A$6) | B20: =IF($E20="","",Меню!$B$6) | C20: =IF($E20="","",Меню!$C$6) | D20: =IF($E20="","",Меню!$D$6) | E20: =IFERROR(IF(IFERROR(INDEX(Рецепты!$H$6:$H$85,MATCH(Меню!$D$6,Рецепты!$H$6:$H$85,0)+14)=Меню!$D$6,FALSE),INDEX(Рецепты!$J$6:$J$85,MATCH(Меню!$D$6,Рецепты!$H$6:$H$85,0)+14),""),"") | F20: =IF($E20="","",INDEX(Рецепты!$K$6:$K$85,MATCH(Меню!$D$6,Рецепты!$H$6:$H$85,0)+14)) | G20: =IF($E20="","",INDEX(Рецепты!$M$6:$M$85,MATCH(Меню!$D$6,Рецепты!$H$6:$H$85,0)+14)) | H20: =IFERROR(IF(IFERROR(INDEX(Рецепты!$H$6:$H$85,MATCH(Меню!$D$6,Рецепты!$H$6:$H$85,0)+14)=Меню!$D$6,FALSE),INDEX(Рецепты!$L$6:$L$85,MATCH(Меню!$D$6,Рецепты!$H$6:$H$85,0)+14),0),0) -> 0 | I20: =IF($F20="","",Меню!$E$6) | J20: =IFERROR($H20*$I20,0) -> 0 | K20: =IFERROR($J20/100*INDEX(Продукты!$G$6:$G$66,MATCH($E20,Продукты!$A$6:$A$66,0)),0) -> 0 | L20: =IFERROR($J20/100*INDEX(Продукты!$H$6:$H$66,MATCH($E20,Продукты!$A$6:$A$66,0)),0) -> 0 | M20: =IFERROR($J20/100*INDEX(Продукты!$I$6:$I$66,MATCH($E20,Продукты!$A$6:$A$66,0)),0) -> 0 | N20: =IFERROR($J20/100*INDEX(Продукты!$J$6:$J$66,MATCH($E20,Продукты!$A$6:$A$66,0)),0) -> 0 | O20: =IFERROR(IF(IFERROR(INDEX(Рецепты!$H$6:$H$85,MATCH(Меню!$D$6,Рецепты!$H$6:$H$85,0)+14)=Меню!$D$6,FALSE),INDEX(Рецепты!$N$6:$N$85,MATCH(Меню!$D$6,Рецепты!$H$6:$H$85,0)+14),""),"")
A21: =IF($E21="","",Меню!$A$6) | B21: =IF($E21="","",Меню!$B$6) | C21: =IF($E21="","",Меню!$C$6) | D21: =IF($E21="","",Меню!$D$6) | E21: =IFERROR(IF(IFERROR(INDEX(Рецепты!$H$6:$H$85,MATCH(Меню!$D$6,Рецепты!$H$6:$H$85,0)+15)=Меню!$D$6,FALSE),INDEX(Рецепты!$J$6:$J$85,MATCH(Меню!$D$6,Рецепты!$H$6:$H$85,0)+15),""),"") | F21: =IF($E21="","",INDEX(Рецепты!$K$6:$K$85,MATCH(Меню!$D$6,Рецепты!$H$6:$H$85,0)+15)) | G21: =IF($E21="","",INDEX(Рецепты!$M$6:$M$85,MATCH(Меню!$D$6,Рецепты!$H$6:$H$85,0)+15)) | H21: =IFERROR(IF(IFERROR(INDEX(Рецепты!$H$6:$H$85,MATCH(Меню!$D$6,Рецепты!$H$6:$H$85,0)+15)=Меню!$D$6,FALSE),INDEX(Рецепты!$L$6:$L$85,MATCH(Меню!$D$6,Рецепты!$H$6:$H$85,0)+15),0),0) -> 0 | I21: =IF($F21="","",Меню!$E$6) | J21: =IFERROR($H21*$I21,0) -> 0 | K21: =IFERROR($J21/100*INDEX(Продукты!$G$6:$G$66,MATCH($E21,Продукты!$A$6:$A$66,0)),0) -> 0 | L21: =IFERROR($J21/100*INDEX(Продукты!$H$6:$H$66,MATCH($E21,Продукты!$A$6:$A$66,0)),0) -> 0 | M21: =IFERROR($J21/100*INDEX(Продукты!$I$6:$I$66,MATCH($E21,Продукты!$A$6:$A$66,0)),0) -> 0 | N21: =IFERROR($J21/100*INDEX(Продукты!$J$6:$J$66,MATCH($E21,Продукты!$A$6:$A$66,0)),0) -> 0 | O21: =IFERROR(IF(IFERROR(INDEX(Рецепты!$H$6:$H$85,MATCH(Меню!$D$6,Рецепты!$H$6:$H$85,0)+15)=Меню!$D$6,FALSE),INDEX(Рецепты!$N$6:$N$85,MATCH(Меню!$D$6,Рецепты!$H$6:$H$85,0)+15),""),"")
A22: =IF($E22="","",Меню!$A$6) | B22: =IF($E22="","",Меню!$B$6) | C22: =IF($E22="","",Меню!$C$6) | D22: =IF($E22="","",Меню!$D$6) | E22: =IFERROR(IF(IFERROR(INDEX(Рецепты!$H$6:$H$85,MATCH(Меню!$D$6,Рецепты!$H$6:$H$85,0)+16)=Меню!$D$6,FALSE),INDEX(Рецепты!$J$6:$J$85,MATCH(Меню!$D$6,Рецепты!$H$6:$H$85,0)+16),""),"") | F22: =IF($E22="","",INDEX(Рецепты!$K$6:$K$85,MATCH(Меню!$D$6,Рецепты!$H$6:$H$85,0)+16)) | G22: =IF($E22="","",INDEX(Рецепты!$M$6:$M$85,MATCH(Меню!$D$6,Рецепты!$H$6:$H$85,0)+16)) | H22: =IFERROR(IF(IFERROR(INDEX(Рецепты!$H$6:$H$85,MATCH(Меню!$D$6,Рецепты!$H$6:$H$85,0)+16)=Меню!$D$6,FALSE),INDEX(Рецепты!$L$6:$L$85,MATCH(Меню!$D$6,Рецепты!$H$6:$H$85,0)+16),0),0) -> 0 | I22: =IF($F22="","",Меню!$E$6) | J22: =IFERROR($H22*$I22,0) -> 0 | K22: =IFERROR($J22/100*INDEX(Продукты!$G$6:$G$66,MATCH($E22,Продукты!$A$6:$A$66,0)),0) -> 0 | L22: =IFERROR($J22/100*INDEX(Продукты!$H$6:$H$66,MATCH($E22,Продукты!$A$6:$A$66,0)),0) -> 0 | M22: =IFERROR($J22/100*INDEX(Продукты!$I$6:$I$66,MATCH($E22,Продукты!$A$6:$A$66,0)),0) -> 0 | N22: =IFERROR($J22/100*INDEX(Продукты!$J$6:$J$66,MATCH($E22,Продукты!$A$6:$A$66,0)),0) -> 0 | O22: =IFERROR(IF(IFERROR(INDEX(Рецепты!$H$6:$H$85,MATCH(Меню!$D$6,Рецепты!$H$6:$H$85,0)+16)=Меню!$D$6,FALSE),INDEX(Рецепты!$N$6:$N$85,MATCH(Меню!$D$6,Рецепты!$H$6:$H$85,0)+16),""),"")
A23: =IF($E23="","",Меню!$A$6) | B23: =IF($E23="","",Меню!$B$6) | C23: =IF($E23="","",Меню!$C$6) | D23: =IF($E23="","",Меню!$D$6) | E23: =IFERROR(IF(IFERROR(INDEX(Рецепты!$H$6:$H$85,MATCH(Меню!$D$6,Рецепты!$H$6:$H$85,0)+17)=Меню!$D$6,FALSE),INDEX(Рецепты!$J$6:$J$85,MATCH(Меню!$D$6,Рецепты!$H$6:$H$85,0)+17),""),"") | F23: =IF($E23="","",INDEX(Рецепты!$K$6:$K$85,MATCH(Меню!$D$6,Рецепты!$H$6:$H$85,0)+17)) | G23: =IF($E23="","",INDEX(Рецепты!$M$6:$M$85,MATCH(Меню!$D$6,Рецепты!$H$6:$H$85,0)+17)) | H23: =IFERROR(IF(IFERROR(INDEX(Рецепты!$H$6:$H$85,MATCH(Меню!$D$6,Рецепты!$H$6:$H$85,0)+17)=Меню!$D$6,FALSE),INDEX(Рецепты!$L$6:$L$85,MATCH(Меню!$D$6,Рецепты!$H$6:$H$85,0)+17),0),0) -> 0 | I23: =IF($F23="","",Меню!$E$6) | J23: =IFERROR($H23*$I23,0) -> 0 | K23: =IFERROR($J23/100*INDEX(Продукты!$G$6:$G$66,MATCH($E23,Продукты!$A$6:$A$66,0)),0) -> 0 | L23: =IFERROR($J23/100*INDEX(Продукты!$H$6:$H$66,MATCH($E23,Продукты!$A$6:$A$66,0)),0) -> 0 | M23: =IFERROR($J23/100*INDEX(Продукты!$I$6:$I$66,MATCH($E23,Продукты!$A$6:$A$66,0)),0) -> 0 | N23: =IFERROR($J23/100*INDEX(Продукты!$J$6:$J$66,MATCH($E23,Продукты!$A$6:$A$66,0)),0) -> 0 | O23: =IFERROR(IF(IFERROR(INDEX(Рецепты!$H$6:$H$85,MATCH(Меню!$D$6,Рецепты!$H$6:$H$85,0)+17)=Меню!$D$6,FALSE),INDEX(Рецепты!$N$6:$N$85,MATCH(Меню!$D$6,Рецепты!$H$6:$H$85,0)+17),""),"")
A24: =IF($E24="","",Меню!$A$6) | B24: =IF($E24="","",Меню!$B$6) | C24: =IF($E24="","",Меню!$C$6) | D24: =IF($E24="","",Меню!$D$6) | E24: =IFERROR(IF(IFERROR(INDEX(Рецепты!$H$6:$H$85,MATCH(Меню!$D$6,Рецепты!$H$6:$H$85,0)+18)=Меню!$D$6,FALSE),INDEX(Рецепты!$J$6:$J$85,MATCH(Меню!$D$6,Рецепты!$H$6:$H$85,0)+18),""),"") | F24: =IF($E24="","",INDEX(Рецепты!$K$6:$K$85,MATCH(Меню!$D$6,Рецепты!$H$6:$H$85,0)+18)) | G24: =IF($E24="","",INDEX(Рецепты!$M$6:$M$85,MATCH(Меню!$D$6,Рецепты!$H$6:$H$85,0)+18)) | H24: =IFERROR(IF(IFERROR(INDEX(Рецепты!$H$6:$H$85,MATCH(Меню!$D$6,Рецепты!$H$6:$H$85,0)+18)=Меню!$D$6,FALSE),INDEX(Рецепты!$L$6:$L$85,MATCH(Меню!$D$6,Рецепты!$H$6:$H$85,0)+18),0),0) -> 0 | I24: =IF($F24="","",Меню!$E$6) | J24: =IFERROR($H24*$I24,0) -> 0 | K24: =IFERROR($J24/100*INDEX(Продукты!$G$6:$G$66,MATCH($E24,Продукты!$A$6:$A$66,0)),0) -> 0 | L24: =IFERROR($J24/100*INDEX(Продукты!$H$6:$H$66,MATCH($E24,Продукты!$A$6:$A$66,0)),0) -> 0 | M24: =IFERROR($J24/100*INDEX(Продукты!$I$6:$I$66,MATCH($E24,Продукты!$A$6:$A$66,0)),0) -> 0 | N24: =IFERROR($J24/100*INDEX(Продукты!$J$6:$J$66,MATCH($E24,Продукты!$A$6:$A$66,0)),0) -> 0 | O24: =IFERROR(IF(IFERROR(INDEX(Рецепты!$H$6:$H$85,MATCH(Меню!$D$6,Рецепты!$H$6:$H$85,0)+18)=Меню!$D$6,FALSE),INDEX(Рецепты!$N$6:$N$85,MATCH(Меню!$D$6,Рецепты!$H$6:$H$85,0)+18),""),"")
A25: =IF($E25="","",Меню!$A$6) | B25: =IF($E25="","",Меню!$B$6) | C25: =IF($E25="","",Меню!$C$6) | D25: =IF($E25="","",Меню!$D$6) | E25: =IFERROR(IF(IFERROR(INDEX(Рецепты!$H$6:$H$85,MATCH(Меню!$D$6,Рецепты!$H$6:$H$85,0)+19)=Меню!$D$6,FALSE),INDEX(Рецепты!$J$6:$J$85,MATCH(Меню!$D$6,Рецепты!$H$6:$H$85,0)+19),""),"") | F25: =IF($E25="","",INDEX(Рецепты!$K$6:$K$85,MATCH(Меню!$D$6,Рецепты!$H$6:$H$85,0)+19)) | G25: =IF($E25="","",INDEX(Рецепты!$M$6:$M$85,MATCH(Меню!$D$6,Рецепты!$H$6:$H$85,0)+19)) | H25: =IFERROR(IF(IFERROR(INDEX(Рецепты!$H$6:$H$85,MATCH(Меню!$D$6,Рецепты!$H$6:$H$85,0)+19)=Меню!$D$6,FALSE),INDEX(Рецепты!$L$6:$L$85,MATCH(Меню!$D$6,Рецепты!$H$6:$H$85,0)+19),0),0) -> 0 | I25: =IF($F25="","",Меню!$E$6) | J25: =IFERROR($H25*$I25,0) -> 0 | K25: =IFERROR($J25/100*INDEX(Продукты!$G$6:$G$66,MATCH($E25,Продукты!$A$6:$A$66,0)),0) -> 0 | L25: =IFERROR($J25/100*INDEX(Продукты!$H$6:$H$66,MATCH($E25,Продукты!$A$6:$A$66,0)),0) -> 0 | M25: =IFERROR($J25/100*INDEX(Продукты!$I$6:$I$66,MATCH($E25,Продукты!$A$6:$A$66,0)),0) -> 0 | N25: =IFERROR($J25/100*INDEX(Продукты!$J$6:$J$66,MATCH($E25,Продукты!$A$6:$A$66,0)),0) -> 0 | O25: =IFERROR(IF(IFERROR(INDEX(Рецепты!$H$6:$H$85,MATCH(Меню!$D$6,Рецепты!$H$6:$H$85,0)+19)=Меню!$D$6,FALSE),INDEX(Рецепты!$N$6:$N$85,MATCH(Меню!$D$6,Рецепты!$H$6:$H$85,0)+19),""),"")
A26: =IF($E26="","",Меню!$A$6) | B26: =IF($E26="","",Меню!$B$6) | C26: =IF($E26="","",Меню!$C$6) | D26: =IF($E26="","",Меню!$D$6) | E26: =IFERROR(IF(IFERROR(INDEX(Рецепты!$H$6:$H$85,MATCH(Меню!$D$6,Рецепты!$H$6:$H$85,0)+20)=Меню!$D$6,FALSE),INDEX(Рецепты!$J$6:$J$85,MATCH(Меню!$D$6,Рецепты!$H$6:$H$85,0)+20),""),"") | F26: =IF($E26="","",INDEX(Рецепты!$K$6:$K$85,MATCH(Меню!$D$6,Рецепты!$H$6:$H$85,0)+20)) | G26: =IF($E26="","",INDEX(Рецепты!$M$6:$M$85,MATCH(Меню!$D$6,Рецепты!$H$6:$H$85,0)+20)) | H26: =IFERROR(IF(IFERROR(INDEX(Рецепты!$H$6:$H$85,MATCH(Меню!$D$6,Рецепты!$H$6:$H$85,0)+20)=Меню!$D$6,FALSE),INDEX(Рецепты!$L$6:$L$85,MATCH(Меню!$D$6,Рецепты!$H$6:$H$85,0)+20),0),0) -> 0 | I26: =IF($F26="","",Меню!$E$6) | J26: =IFERROR($H26*$I26,0) -> 0 | K26: =IFERROR($J26/100*INDEX(Продукты!$G$6:$G$66,MATCH($E26,Продукты!$A$6:$A$66,0)),0) -> 0 | L26: =IFERROR($J26/100*INDEX(Продукты!$H$6:$H$66,MATCH($E26,Продукты!$A$6:$A$66,0)),0) -> 0 | M26: =IFERROR($J26/100*INDEX(Продукты!$I$6:$I$66,MATCH($E26,Продукты!$A$6:$A$66,0)),0) -> 0 | N26: =IFERROR($J26/100*INDEX(Продукты!$J$6:$J$66,MATCH($E26,Продукты!$A$6:$A$66,0)),0) -> 0 | O26: =IFERROR(IF(IFERROR(INDEX(Рецепты!$H$6:$H$85,MATCH(Меню!$D$6,Рецепты!$H$6:$H$85,0)+20)=Меню!$D$6,FALSE),INDEX(Рецепты!$N$6:$N$85,MATCH(Меню!$D$6,Рецепты!$H$6:$H$85,0)+20),""),"")
A27: =IF($E27="","",Меню!$A$6) | B27: =IF($E27="","",Меню!$B$6) | C27: =IF($E27="","",Меню!$C$6) | D27: =IF($E27="","",Меню!$D$6) | E27: =IFERROR(IF(IFERROR(INDEX(Рецепты!$H$6:$H$85,MATCH(Меню!$D$6,Рецепты!$H$6:$H$85,0)+21)=Меню!$D$6,FALSE),INDEX(Рецепты!$J$6:$J$85,MATCH(Меню!$D$6,Рецепты!$H$6:$H$85,0)+21),""),"") | F27: =IF($E27="","",INDEX(Рецепты!$K$6:$K$85,MATCH(Меню!$D$6,Рецепты!$H$6:$H$85,0)+21)) | G27: =IF($E27="","",INDEX(Рецепты!$M$6:$M$85,MATCH(Меню!$D$6,Рецепты!$H$6:$H$85,0)+21)) | H27: =IFERROR(IF(IFERROR(INDEX(Рецепты!$H$6:$H$85,MATCH(Меню!$D$6,Рецепты!$H$6:$H$85,0)+21)=Меню!$D$6,FALSE),INDEX(Рецепты!$L$6:$L$85,MATCH(Меню!$D$6,Рецепты!$H$6:$H$85,0)+21),0),0) -> 0 | I27: =IF($F27="","",Меню!$E$6) | J27: =IFERROR($H27*$I27,0) -> 0 | K27: =IFERROR($J27/100*INDEX(Продукты!$G$6:$G$66,MATCH($E27,Продукты!$A$6:$A$66,0)),0) -> 0 | L27: =IFERROR($J27/100*INDEX(Продукты!$H$6:$H$66,MATCH($E27,Продукты!$A$6:$A$66,0)),0) -> 0 | M27: =IFERROR($J27/100*INDEX(Продукты!$I$6:$I$66,MATCH($E27,Продукты!$A$6:$A$66,0)),0) -> 0 | N27: =IFERROR($J27/100*INDEX(Продукты!$J$6:$J$66,MATCH($E27,Продукты!$A$6:$A$66,0)),0) -> 0 | O27: =IFERROR(IF(IFERROR(INDEX(Рецепты!$H$6:$H$85,MATCH(Меню!$D$6,Рецепты!$H$6:$H$85,0)+21)=Меню!$D$6,FALSE),INDEX(Рецепты!$N$6:$N$85,MATCH(Меню!$D$6,Рецепты!$H$6:$H$85,0)+21),""),"")
A28: =IF($E28="","",Меню!$A$6) | B28: =IF($E28="","",Меню!$B$6) | C28: =IF($E28="","",Меню!$C$6) | D28: =IF($E28="","",Меню!$D$6) | E28: =IFERROR(IF(IFERROR(INDEX(Рецепты!$H$6:$H$85,MATCH(Меню!$D$6,Рецепты!$H$6:$H$85,0)+22)=Меню!$D$6,FALSE),INDEX(Рецепты!$J$6:$J$85,MATCH(Меню!$D$6,Рецепты!$H$6:$H$85,0)+22),""),"") | F28: =IF($E28="","",INDEX(Рецепты!$K$6:$K$85,MATCH(Меню!$D$6,Рецепты!$H$6:$H$85,0)+22)) | G28: =IF($E28="","",INDEX(Рецепты!$M$6:$M$85,MATCH(Меню!$D$6,Рецепты!$H$6:$H$85,0)+22)) | H28: =IFERROR(IF(IFERROR(INDEX(Рецепты!$H$6:$H$85,MATCH(Меню!$D$6,Рецепты!$H$6:$H$85,0)+22)=Меню!$D$6,FALSE),INDEX(Рецепты!$L$6:$L$85,MATCH(Меню!$D$6,Рецепты!$H$6:$H$85,0)+22),0),0) -> 0 | I28: =IF($F28="","",Меню!$E$6) | J28: =IFERROR($H28*$I28,0) -> 0 | K28: =IFERROR($J28/100*INDEX(Продукты!$G$6:$G$66,MATCH($E28,Продукты!$A$6:$A$66,0)),0) -> 0 | L28: =IFERROR($J28/100*INDEX(Продукты!$H$6:$H$66,MATCH($E28,Продукты!$A$6:$A$66,0)),0) -> 0 | M28: =IFERROR($J28/100*INDEX(Продукты!$I$6:$I$66,MATCH($E28,Продукты!$A$6:$A$66,0)),0) -> 0 | N28: =IFERROR($J28/100*INDEX(Продукты!$J$6:$J$66,MATCH($E28,Продукты!$A$6:$A$66,0)),0) -> 0 | O28: =IFERROR(IF(IFERROR(INDEX(Рецепты!$H$6:$H$85,MATCH(Меню!$D$6,Рецепты!$H$6:$H$85,0)+22)=Меню!$D$6,FALSE),INDEX(Рецепты!$N$6:$N$85,MATCH(Меню!$D$6,Рецепты!$H$6:$H$85,0)+22),""),"")
A29: =IF($E29="","",Меню!$A$6) | B29: =IF($E29="","",Меню!$B$6) | C29: =IF($E29="","",Меню!$C$6) | D29: =IF($E29="","",Меню!$D$6) | E29: =IFERROR(IF(IFERROR(INDEX(Рецепты!$H$6:$H$85,MATCH(Меню!$D$6,Рецепты!$H$6:$H$85,0)+23)=Меню!$D$6,FALSE),INDEX(Рецепты!$J$6:$J$85,MATCH(Меню!$D$6,Рецепты!$H$6:$H$85,0)+23),""),"") | F29: =IF($E29="","",INDEX(Рецепты!$K$6:$K$85,MATCH(Меню!$D$6,Рецепты!$H$6:$H$85,0)+23)) | G29: =IF($E29="","",INDEX(Рецепты!$M$6:$M$85,MATCH(Меню!$D$6,Рецепты!$H$6:$H$85,0)+23)) | H29: =IFERROR(IF(IFERROR(INDEX(Рецепты!$H$6:$H$85,MATCH(Меню!$D$6,Рецепты!$H$6:$H$85,0)+23)=Меню!$D$6,FALSE),INDEX(Рецепты!$L$6:$L$85,MATCH(Меню!$D$6,Рецепты!$H$6:$H$85,0)+23),0),0) -> 0 | I29: =IF($F29="","",Меню!$E$6) | J29: =IFERROR($H29*$I29,0) -> 0 | K29: =IFERROR($J29/100*INDEX(Продукты!$G$6:$G$66,MATCH($E29,Продукты!$A$6:$A$66,0)),0) -> 0 | L29: =IFERROR($J29/100*INDEX(Продукты!$H$6:$H$66,MATCH($E29,Продукты!$A$6:$A$66,0)),0) -> 0 | M29: =IFERROR($J29/100*INDEX(Продукты!$I$6:$I$66,MATCH($E29,Продукты!$A$6:$A$66,0)),0) -> 0 | N29: =IFERROR($J29/100*INDEX(Продукты!$J$6:$J$66,MATCH($E29,Продукты!$A$6:$A$66,0)),0) -> 0 | O29: =IFERROR(IF(IFERROR(INDEX(Рецепты!$H$6:$H$85,MATCH(Меню!$D$6,Рецепты!$H$6:$H$85,0)+23)=Меню!$D$6,FALSE),INDEX(Рецепты!$N$6:$N$85,MATCH(Меню!$D$6,Рецепты!$H$6:$H$85,0)+23),""),"")
A30: =IF($E30="","",Меню!$A$6) | B30: =IF($E30="","",Меню!$B$6) | C30: =IF($E30="","",Меню!$C$6) | D30: =IF($E30="","",Меню!$D$6) | E30: =IFERROR(IF(IFERROR(INDEX(Рецепты!$H$6:$H$85,MATCH(Меню!$D$6,Рецепты!$H$6:$H$85,0)+24)=Меню!$D$6,FALSE),INDEX(Рецепты!$J$6:$J$85,MATCH(Меню!$D$6,Рецепты!$H$6:$H$85,0)+24),""),"") | F30: =IF($E30="","",INDEX(Рецепты!$K$6:$K$85,MATCH(Меню!$D$6,Рецепты!$H$6:$H$85,0)+24)) | G30: =IF($E30="","",INDEX(Рецепты!$M$6:$M$85,MATCH(Меню!$D$6,Рецепты!$H$6:$H$85,0)+24)) | H30: =IFERROR(IF(IFERROR(INDEX(Рецепты!$H$6:$H$85,MATCH(Меню!$D$6,Рецепты!$H$6:$H$85,0)+24)=Меню!$D$6,FALSE),INDEX(Рецепты!$L$6:$L$85,MATCH(Меню!$D$6,Рецепты!$H$6:$H$85,0)+24),0),0) -> 0 | I30: =IF($F30="","",Меню!$E$6) | J30: =IFERROR($H30*$I30,0) -> 0 | K30: =IFERROR($J30/100*INDEX(Продукты!$G$6:$G$66,MATCH($E30,Продукты!$A$6:$A$66,0)),0) -> 0 | L30: =IFERROR($J30/100*INDEX(Продукты!$H$6:$H$66,MATCH($E30,Продукты!$A$6:$A$66,0)),0) -> 0 | M30: =IFERROR($J30/100*INDEX(Продукты!$I$6:$I$66,MATCH($E30,Продукты!$A$6:$A$66,0)),0) -> 0 | N30: =IFERROR($J30/100*INDEX(Продукты!$J$6:$J$66,MATCH($E30,Продукты!$A$6:$A$66,0)),0) -> 0 | O30: =IFERROR(IF(IFERROR(INDEX(Рецепты!$H$6:$H$85,MATCH(Меню!$D$6,Рецепты!$H$6:$H$85,0)+24)=Меню!$D$6,FALSE),INDEX(Рецепты!$N$6:$N$85,MATCH(Меню!$D$6,Рецепты!$H$6:$H$85,0)+24),""),"")
A31: =IF($E31="","",Меню!$A$7) | B31: =IF($E31="","",Меню!$B$7) | C31: =IF($E31="","",Меню!$C$7) | D31: =IF($E31="","",Меню!$D$7) | E31: =IFERROR(IF(IFERROR(INDEX(Рецепты!$H$6:$H$85,MATCH(Меню!$D$7,Рецепты!$H$6:$H$85,0)+0)=Меню!$D$7,FALSE),INDEX(Рецепты!$J$6:$J$85,MATCH(Меню!$D$7,Рецепты!$H$6:$H$85,0)+0),""),"") | F31: =IF($E31="","",INDEX(Рецепты!$K$6:$K$85,MATCH(Меню!$D$7,Рецепты!$H$6:$H$85,0)+0)) | G31: =IF($E31="","",INDEX(Рецепты!$M$6:$M$85,MATCH(Меню!$D$7,Рецепты!$H$6:$H$85,0)+0)) | H31: =IFERROR(IF(IFERROR(INDEX(Рецепты!$H$6:$H$85,MATCH(Меню!$D$7,Рецепты!$H$6:$H$85,0)+0)=Меню!$D$7,FALSE),INDEX(Рецепты!$L$6:$L$85,MATCH(Меню!$D$7,Рецепты!$H$6:$H$85,0)+0),0),0) -> 0 | I31: =IF($F31="","",Меню!$E$7) | J31: =IFERROR($H31*$I31,0) -> 0 | K31: =IFERROR($J31/100*INDEX(Продукты!$G$6:$G$66,MATCH($E31,Продукты!$A$6:$A$66,0)),0) -> 0 | L31: =IFERROR($J31/100*INDEX(Продукты!$H$6:$H$66,MATCH($E31,Продукты!$A$6:$A$66,0)),0) -> 0 | M31: =IFERROR($J31/100*INDEX(Продукты!$I$6:$I$66,MATCH($E31,Продукты!$A$6:$A$66,0)),0) -> 0 | N31: =IFERROR($J31/100*INDEX(Продукты!$J$6:$J$66,MATCH($E31,Продукты!$A$6:$A$66,0)),0) -> 0 | O31: =IFERROR(IF(IFERROR(INDEX(Рецепты!$H$6:$H$85,MATCH(Меню!$D$7,Рецепты!$H$6:$H$85,0)+0)=Меню!$D$7,FALSE),INDEX(Рецепты!$N$6:$N$85,MATCH(Меню!$D$7,Рецепты!$H$6:$H$85,0)+0),""),"")
A32: =IF($E32="","",Меню!$A$7) | B32: =IF($E32="","",Меню!$B$7) | C32: =IF($E32="","",Меню!$C$7) | D32: =IF($E32="","",Меню!$D$7) | E32: =IFERROR(IF(IFERROR(INDEX(Рецепты!$H$6:$H$85,MATCH(Меню!$D$7,Рецепты!$H$6:$H$85,0)+1)=Меню!$D$7,FALSE),INDEX(Рецепты!$J$6:$J$85,MATCH(Меню!$D$7,Рецепты!$H$6:$H$85,0)+1),""),"") | F32: =IF($E32="","",INDEX(Рецепты!$K$6:$K$85,MATCH(Меню!$D$7,Рецепты!$H$6:$H$85,0)+1)) | G32: =IF($E32="","",INDEX(Рецепты!$M$6:$M$85,MATCH(Меню!$D$7,Рецепты!$H$6:$H$85,0)+1)) | H32: =IFERROR(IF(IFERROR(INDEX(Рецепты!$H$6:$H$85,MATCH(Меню!$D$7,Рецепты!$H$6:$H$85,0)+1)=Меню!$D$7,FALSE),INDEX(Рецепты!$L$6:$L$85,MATCH(Меню!$D$7,Рецепты!$H$6:$H$85,0)+1),0),0) -> 0 | I32: =IF($F32="","",Меню!$E$7) | J32: =IFERROR($H32*$I32,0) -> 0 | K32: =IFERROR($J32/100*INDEX(Продукты!$G$6:$G$66,MATCH($E32,Продукты!$A$6:$A$66,0)),0) -> 0 | L32: =IFERROR($J32/100*INDEX(Продукты!$H$6:$H$66,MATCH($E32,Продукты!$A$6:$A$66,0)),0) -> 0 | M32: =IFERROR($J32/100*INDEX(Продукты!$I$6:$I$66,MATCH($E32,Продукты!$A$6:$A$66,0)),0) -> 0 | N32: =IFERROR($J32/100*INDEX(Продукты!$J$6:$J$66,MATCH($E32,Продукты!$A$6:$A$66,0)),0) -> 0 | O32: =IFERROR(IF(IFERROR(INDEX(Рецепты!$H$6:$H$85,MATCH(Меню!$D$7,Рецепты!$H$6:$H$85,0)+1)=Меню!$D$7,FALSE),INDEX(Рецепты!$N$6:$N$85,MATCH(Меню!$D$7,Рецепты!$H$6:$H$85,0)+1),""),"")
A33: =IF($E33="","",Меню!$A$7) | B33: =IF($E33="","",Меню!$B$7) | C33: =IF($E33="","",Меню!$C$7) | D33: =IF($E33="","",Меню!$D$7) | E33: =IFERROR(IF(IFERROR(INDEX(Рецепты!$H$6:$H$85,MATCH(Меню!$D$7,Рецепты!$H$6:$H$85,0)+2)=Меню!$D$7,FALSE),INDEX(Рецепты!$J$6:$J$85,MATCH(Меню!$D$7,Рецепты!$H$6:$H$85,0)+2),""),"") | F33: =IF($E33="","",INDEX(Рецепты!$K$6:$K$85,MATCH(Меню!$D$7,Рецепты!$H$6:$H$85,0)+2)) | G33: =IF($E33="","",INDEX(Рецепты!$M$6:$M$85,MATCH(Меню!$D$7,Рецепты!$H$6:$H$85,0)+2)) | H33: =IFERROR(IF(IFERROR(INDEX(Рецепты!$H$6:$H$85,MATCH(Меню!$D$7,Рецепты!$H$6:$H$85,0)+2)=Меню!$D$7,FALSE),INDEX(Рецепты!$L$6:$L$85,MATCH(Меню!$D$7,Рецепты!$H$6:$H$85,0)+2),0),0) -> 0 | I33: =IF($F33="","",Меню!$E$7) | J33: =IFERROR($H33*$I33,0) -> 0 | K33: =IFERROR($J33/100*INDEX(Продукты!$G$6:$G$66,MATCH($E33,Продукты!$A$6:$A$66,0)),0) -> 0 | L33: =IFERROR($J33/100*INDEX(Продукты!$H$6:$H$66,MATCH($E33,Продукты!$A$6:$A$66,0)),0) -> 0 | M33: =IFERROR($J33/100*INDEX(Продукты!$I$6:$I$66,MATCH($E33,Продукты!$A$6:$A$66,0)),0) -> 0 | N33: =IFERROR($J33/100*INDEX(Продукты!$J$6:$J$66,MATCH($E33,Продукты!$A$6:$A$66,0)),0) -> 0 | O33: =IFERROR(IF(IFERROR(INDEX(Рецепты!$H$6:$H$85,MATCH(Меню!$D$7,Рецепты!$H$6:$H$85,0)+2)=Меню!$D$7,FALSE),INDEX(Рецепты!$N$6:$N$85,MATCH(Меню!$D$7,Рецепты!$H$6:$H$85,0)+2),""),"")
A34: =IF($E34="","",Меню!$A$7) | B34: =IF($E34="","",Меню!$B$7) | C34: =IF($E34="","",Меню!$C$7) | D34: =IF($E34="","",Меню!$D$7) | E34: =IFERROR(IF(IFERROR(INDEX(Рецепты!$H$6:$H$85,MATCH(Меню!$D$7,Рецепты!$H$6:$H$85,0)+3)=Меню!$D$7,FALSE),INDEX(Рецепты!$J$6:$J$85,MATCH(Меню!$D$7,Рецепты!$H$6:$H$85,0)+3),""),"") | F34: =IF($E34="","",INDEX(Рецепты!$K$6:$K$85,MATCH(Меню!$D$7,Рецепты!$H$6:$H$85,0)+3)) | G34: =IF($E34="","",INDEX(Рецепты!$M$6:$M$85,MATCH(Меню!$D$7,Рецепты!$H$6:$H$85,0)+3)) | H34: =IFERROR(IF(IFERROR(INDEX(Рецепты!$H$6:$H$85,MATCH(Меню!$D$7,Рецепты!$H$6:$H$85,0)+3)=Меню!$D$7,FALSE),INDEX(Рецепты!$L$6:$L$85,MATCH(Меню!$D$7,Рецепты!$H$6:$H$85,0)+3),0),0) -> 0 | I34: =IF($F34="","",Меню!$E$7) | J34: =IFERROR($H34*$I34,0) -> 0 | K34: =IFERROR($J34/100*INDEX(Продукты!$G$6:$G$66,MATCH($E34,Продукты!$A$6:$A$66,0)),0) -> 0 | L34: =IFERROR($J34/100*INDEX(Продукты!$H$6:$H$66,MATCH($E34,Продукты!$A$6:$A$66,0)),0) -> 0 | M34: =IFERROR($J34/100*INDEX(Продукты!$I$6:$I$66,MATCH($E34,Продукты!$A$6:$A$66,0)),0) -> 0 | N34: =IFERROR($J34/100*INDEX(Продукты!$J$6:$J$66,MATCH($E34,Продукты!$A$6:$A$66,0)),0) -> 0 | O34: =IFERROR(IF(IFERROR(INDEX(Рецепты!$H$6:$H$85,MATCH(Меню!$D$7,Рецепты!$H$6:$H$85,0)+3)=Меню!$D$7,FALSE),INDEX(Рецепты!$N$6:$N$85,MATCH(Меню!$D$7,Рецепты!$H$6:$H$85,0)+3),""),"")
A35: =IF($E35="","",Меню!$A$7) | B35: =IF($E35="","",Меню!$B$7) | C35: =IF($E35="","",Меню!$C$7) | D35: =IF($E35="","",Меню!$D$7) | E35: =IFERROR(IF(IFERROR(INDEX(Рецепты!$H$6:$H$85,MATCH(Меню!$D$7,Рецепты!$H$6:$H$85,0)+4)=Меню!$D$7,FALSE),INDEX(Рецепты!$J$6:$J$85,MATCH(Меню!$D$7,Рецепты!$H$6:$H$85,0)+4),""),"") | F35: =IF($E35="","",INDEX(Рецепты!$K$6:$K$85,MATCH(Меню!$D$7,Рецепты!$H$6:$H$85,0)+4)) | G35: =IF($E35="","",INDEX(Рецепты!$M$6:$M$85,MATCH(Меню!$D$7,Рецепты!$H$6:$H$85,0)+4)) | H35: =IFERROR(IF(IFERROR(INDEX(Рецепты!$H$6:$H$85,MATCH(Меню!$D$7,Рецепты!$H$6:$H$85,0)+4)=Меню!$D$7,FALSE),INDEX(Рецепты!$L$6:$L$85,MATCH(Меню!$D$7,Рецепты!$H$6:$H$85,0)+4),0),0) -> 0 | I35: =IF($F35="","",Меню!$E$7) | J35: =IFERROR($H35*$I35,0) -> 0 | K35: =IFERROR($J35/100*INDEX(Продукты!$G$6:$G$66,MATCH($E35,Продукты!$A$6:$A$66,0)),0) -> 0 | L35: =IFERROR($J35/100*INDEX(Продукты!$H$6:$H$66,MATCH($E35,Продукты!$A$6:$A$66,0)),0) -> 0 | M35: =IFERROR($J35/100*INDEX(Продукты!$I$6:$I$66,MATCH($E35,Продукты!$A$6:$A$66,0)),0) -> 0 | N35: =IFERROR($J35/100*INDEX(Продукты!$J$6:$J$66,MATCH($E35,Продукты!$A$6:$A$66,0)),0) -> 0 | O35: =IFERROR(IF(IFERROR(INDEX(Рецепты!$H$6:$H$85,MATCH(Меню!$D$7,Рецепты!$H$6:$H$85,0)+4)=Меню!$D$7,FALSE),INDEX(Рецепты!$N$6:$N$85,MATCH(Меню!$D$7,Рецепты!$H$6:$H$85,0)+4),""),"")
A36: =IF($E36="","",Меню!$A$7) | B36: =IF($E36="","",Меню!$B$7) | C36: =IF($E36="","",Меню!$C$7) | D36: =IF($E36="","",Меню!$D$7) | E36: =IFERROR(IF(IFERROR(INDEX(Рецепты!$H$6:$H$85,MATCH(Меню!$D$7,Рецепты!$H$6:$H$85,0)+5)=Меню!$D$7,FALSE),INDEX(Рецепты!$J$6:$J$85,MATCH(Меню!$D$7,Рецепты!$H$6:$H$85,0)+5),""),"") | F36: =IF($E36="","",INDEX(Рецепты!$K$6:$K$85,MATCH(Меню!$D$7,Рецепты!$H$6:$H$85,0)+5)) | G36: =IF($E36="","",INDEX(Рецепты!$M$6:$M$85,MATCH(Меню!$D$7,Рецепты!$H$6:$H$85,0)+5)) | H36: =IFERROR(IF(IFERROR(INDEX(Рецепты!$H$6:$H$85,MATCH(Меню!$D$7,Рецепты!$H$6:$H$85,0)+5)=Меню!$D$7,FALSE),INDEX(Рецепты!$L$6:$L$85,MATCH(Меню!$D$7,Рецепты!$H$6:$H$85,0)+5),0),0) -> 0 | I36: =IF($F36="","",Меню!$E$7) | J36: =IFERROR($H36*$I36,0) -> 0 | K36: =IFERROR($J36/100*INDEX(Продукты!$G$6:$G$66,MATCH($E36,Продукты!$A$6:$A$66,0)),0) -> 0 | L36: =IFERROR($J36/100*INDEX(Продукты!$H$6:$H$66,MATCH($E36,Продукты!$A$6:$A$66,0)),0) -> 0 | M36: =IFERROR($J36/100*INDEX(Продукты!$I$6:$I$66,MATCH($E36,Продукты!$A$6:$A$66,0)),0) -> 0 | N36: =IFERROR($J36/100*INDEX(Продукты!$J$6:$J$66,MATCH($E36,Продукты!$A$6:$A$66,0)),0) -> 0 | O36: =IFERROR(IF(IFERROR(INDEX(Рецепты!$H$6:$H$85,MATCH(Меню!$D$7,Рецепты!$H$6:$H$85,0)+5)=Меню!$D$7,FALSE),INDEX(Рецепты!$N$6:$N$85,MATCH(Меню!$D$7,Рецепты!$H$6:$H$85,0)+5),""),"")
A37: =IF($E37="","",Меню!$A$7) | B37: =IF($E37="","",Меню!$B$7) | C37: =IF($E37="","",Меню!$C$7) | D37: =IF($E37="","",Меню!$D$7) | E37: =IFERROR(IF(IFERROR(INDEX(Рецепты!$H$6:$H$85,MATCH(Меню!$D$7,Рецепты!$H$6:$H$85,0)+6)=Меню!$D$7,FALSE),INDEX(Рецепты!$J$6:$J$85,MATCH(Меню!$D$7,Рецепты!$H$6:$H$85,0)+6),""),"") | F37: =IF($E37="","",INDEX(Рецепты!$K$6:$K$85,MATCH(Меню!$D$7,Рецепты!$H$6:$H$85,0)+6)) | G37: =IF($E37="","",INDEX(Рецепты!$M$6:$M$85,MATCH(Меню!$D$7,Рецепты!$H$6:$H$85,0)+6)) | H37: =IFERROR(IF(IFERROR(INDEX(Рецепты!$H$6:$H$85,MATCH(Меню!$D$7,Рецепты!$H$6:$H$85,0)+6)=Меню!$D$7,FALSE),INDEX(Рецепты!$L$6:$L$85,MATCH(Меню!$D$7,Рецепты!$H$6:$H$85,0)+6),0),0) -> 0 | I37: =IF($F37="","",Меню!$E$7) | J37: =IFERROR($H37*$I37,0) -> 0 | K37: =IFERROR($J37/100*INDEX(Продукты!$G$6:$G$66,MATCH($E37,Продукты!$A$6:$A$66,0)),0) -> 0 | L37: =IFERROR($J37/100*INDEX(Продукты!$H$6:$H$66,MATCH($E37,Продукты!$A$6:$A$66,0)),0) -> 0 | M37: =IFERROR($J37/100*INDEX(Продукты!$I$6:$I$66,MATCH($E37,Продукты!$A$6:$A$66,0)),0) -> 0 | N37: =IFERROR($J37/100*INDEX(Продукты!$J$6:$J$66,MATCH($E37,Продукты!$A$6:$A$66,0)),0) -> 0 | O37: =IFERROR(IF(IFERROR(INDEX(Рецепты!$H$6:$H$85,MATCH(Меню!$D$7,Рецепты!$H$6:$H$85,0)+6)=Меню!$D$7,FALSE),INDEX(Рецепты!$N$6:$N$85,MATCH(Меню!$D$7,Рецепты!$H$6:$H$85,0)+6),""),"")
A38: =IF($E38="","",Меню!$A$7) | B38: =IF($E38="","",Меню!$B$7) | C38: =IF($E38="","",Меню!$C$7) | D38: =IF($E38="","",Меню!$D$7) | E38: =IFERROR(IF(IFERROR(INDEX(Рецепты!$H$6:$H$85,MATCH(Меню!$D$7,Рецепты!$H$6:$H$85,0)+7)=Меню!$D$7,FALSE),INDEX(Рецепты!$J$6:$J$85,MATCH(Меню!$D$7,Рецепты!$H$6:$H$85,0)+7),""),"") | F38: =IF($E38="","",INDEX(Рецепты!$K$6:$K$85,MATCH(Меню!$D$7,Рецепты!$H$6:$H$85,0)+7)) | G38: =IF($E38="","",INDEX(Рецепты!$M$6:$M$85,MATCH(Меню!$D$7,Рецепты!$H$6:$H$85,0)+7)) | H38: =IFERROR(IF(IFERROR(INDEX(Рецепты!$H$6:$H$85,MATCH(Меню!$D$7,Рецепты!$H$6:$H$85,0)+7)=Меню!$D$7,FALSE),INDEX(Рецепты!$L$6:$L$85,MATCH(Меню!$D$7,Рецепты!$H$6:$H$85,0)+7),0),0) -> 0 | I38: =IF($F38="","",Меню!$E$7) | J38: =IFERROR($H38*$I38,0) -> 0 | K38: =IFERROR($J38/100*INDEX(Продукты!$G$6:$G$66,MATCH($E38,Продукты!$A$6:$A$66,0)),0) -> 0 | L38: =IFERROR($J38/100*INDEX(Продукты!$H$6:$H$66,MATCH($E38,Продукты!$A$6:$A$66,0)),0) -> 0 | M38: =IFERROR($J38/100*INDEX(Продукты!$I$6:$I$66,MATCH($E38,Продукты!$A$6:$A$66,0)),0) -> 0 | N38: =IFERROR($J38/100*INDEX(Продукты!$J$6:$J$66,MATCH($E38,Продукты!$A$6:$A$66,0)),0) -> 0 | O38: =IFERROR(IF(IFERROR(INDEX(Рецепты!$H$6:$H$85,MATCH(Меню!$D$7,Рецепты!$H$6:$H$85,0)+7)=Меню!$D$7,FALSE),INDEX(Рецепты!$N$6:$N$85,MATCH(Меню!$D$7,Рецепты!$H$6:$H$85,0)+7),""),"")
A39: =IF($E39="","",Меню!$A$7) | B39: =IF($E39="","",Меню!$B$7) | C39: =IF($E39="","",Меню!$C$7) | D39: =IF($E39="","",Меню!$D$7) | E39: =IFERROR(IF(IFERROR(INDEX(Рецепты!$H$6:$H$85,MATCH(Меню!$D$7,Рецепты!$H$6:$H$85,0)+8)=Меню!$D$7,FALSE),INDEX(Рецепты!$J$6:$J$85,MATCH(Меню!$D$7,Рецепты!$H$6:$H$85,0)+8),""),"") | F39: =IF($E39="","",INDEX(Рецепты!$K$6:$K$85,MATCH(Меню!$D$7,Рецепты!$H$6:$H$85,0)+8)) | G39: =IF($E39="","",INDEX(Рецепты!$M$6:$M$85,MATCH(Меню!$D$7,Рецепты!$H$6:$H$85,0)+8)) | H39: =IFERROR(IF(IFERROR(INDEX(Рецепты!$H$6:$H$85,MATCH(Меню!$D$7,Рецепты!$H$6:$H$85,0)+8)=Меню!$D$7,FALSE),INDEX(Рецепты!$L$6:$L$85,MATCH(Меню!$D$7,Рецепты!$H$6:$H$85,0)+8),0),0) -> 0 | I39: =IF($F39="","",Меню!$E$7) | J39: =IFERROR($H39*$I39,0) -> 0 | K39: =IFERROR($J39/100*INDEX(Продукты!$G$6:$G$66,MATCH($E39,Продукты!$A$6:$A$66,0)),0) -> 0 | L39: =IFERROR($J39/100*INDEX(Продукты!$H$6:$H$66,MATCH($E39,Продукты!$A$6:$A$66,0)),0) -> 0 | M39: =IFERROR($J39/100*INDEX(Продукты!$I$6:$I$66,MATCH($E39,Продукты!$A$6:$A$66,0)),0) -> 0 | N39: =IFERROR($J39/100*INDEX(Продукты!$J$6:$J$66,MATCH($E39,Продукты!$A$6:$A$66,0)),0) -> 0 | O39: =IFERROR(IF(IFERROR(INDEX(Рецепты!$H$6:$H$85,MATCH(Меню!$D$7,Рецепты!$H$6:$H$85,0)+8)=Меню!$D$7,FALSE),INDEX(Рецепты!$N$6:$N$85,MATCH(Меню!$D$7,Рецепты!$H$6:$H$85,0)+8),""),"")
A40: =IF($E40="","",Меню!$A$7) | B40: =IF($E40="","",Меню!$B$7) | C40: =IF($E40="","",Меню!$C$7) | D40: =IF($E40="","",Меню!$D$7) | E40: =IFERROR(IF(IFERROR(INDEX(Рецепты!$H$6:$H$85,MATCH(Меню!$D$7,Рецепты!$H$6:$H$85,0)+9)=Меню!$D$7,FALSE),INDEX(Рецепты!$J$6:$J$85,MATCH(Меню!$D$7,Рецепты!$H$6:$H$85,0)+9),""),"") | F40: =IF($E40="","",INDEX(Рецепты!$K$6:$K$85,MATCH(Меню!$D$7,Рецепты!$H$6:$H$85,0)+9)) | G40: =IF($E40="","",INDEX(Рецепты!$M$6:$M$85,MATCH(Меню!$D$7,Рецепты!$H$6:$H$85,0)+9)) | H40: =IFERROR(IF(IFERROR(INDEX(Рецепты!$H$6:$H$85,MATCH(Меню!$D$7,Рецепты!$H$6:$H$85,0)+9)=Меню!$D$7,FALSE),INDEX(Рецепты!$L$6:$L$85,MATCH(Меню!$D$7,Рецепты!$H$6:$H$85,0)+9),0),0) -> 0 | I40: =IF($F40="","",Меню!$E$7) | J40: =IFERROR($H40*$I40,0) -> 0 | K40: =IFERROR($J40/100*INDEX(Продукты!$G$6:$G$66,MATCH($E40,Продукты!$A$6:$A$66,0)),0) -> 0 | L40: =IFERROR($J40/100*INDEX(Продукты!$H$6:$H$66,MATCH($E40,Продукты!$A$6:$A$66,0)),0) -> 0 | M40: =IFERROR($J40/100*INDEX(Продукты!$I$6:$I$66,MATCH($E40,Продукты!$A$6:$A$66,0)),0) -> 0 | N40: =IFERROR($J40/100*INDEX(Продукты!$J$6:$J$66,MATCH($E40,Продукты!$A$6:$A$66,0)),0) -> 0 | O40: =IFERROR(IF(IFERROR(INDEX(Рецепты!$H$6:$H$85,MATCH(Меню!$D$7,Рецепты!$H$6:$H$85,0)+9)=Меню!$D$7,FALSE),INDEX(Рецепты!$N$6:$N$85,MATCH(Меню!$D$7,Рецепты!$H$6:$H$85,0)+9),""),"")
A41: =IF($E41="","",Меню!$A$7) | B41: =IF($E41="","",Меню!$B$7) | C41: =IF($E41="","",Меню!$C$7) | D41: =IF($E41="","",Меню!$D$7) | E41: =IFERROR(IF(IFERROR(INDEX(Рецепты!$H$6:$H$85,MATCH(Меню!$D$7,Рецепты!$H$6:$H$85,0)+10)=Меню!$D$7,FALSE),INDEX(Рецепты!$J$6:$J$85,MATCH(Меню!$D$7,Рецепты!$H$6:$H$85,0)+10),""),"") | F41: =IF($E41="","",INDEX(Рецепты!$K$6:$K$85,MATCH(Меню!$D$7,Рецепты!$H$6:$H$85,0)+10)) | G41: =IF($E41="","",INDEX(Рецепты!$M$6:$M$85,MATCH(Меню!$D$7,Рецепты!$H$6:$H$85,0)+10)) | H41: =IFERROR(IF(IFERROR(INDEX(Рецепты!$H$6:$H$85,MATCH(Меню!$D$7,Рецепты!$H$6:$H$85,0)+10)=Меню!$D$7,FALSE),INDEX(Рецепты!$L$6:$L$85,MATCH(Меню!$D$7,Рецепты!$H$6:$H$85,0)+10),0),0) -> 0 | I41: =IF($F41="","",Меню!$E$7) | J41: =IFERROR($H41*$I41,0) -> 0 | K41: =IFERROR($J41/100*INDEX(Продукты!$G$6:$G$66,MATCH($E41,Продукты!$A$6:$A$66,0)),0) -> 0 | L41: =IFERROR($J41/100*INDEX(Продукты!$H$6:$H$66,MATCH($E41,Продукты!$A$6:$A$66,0)),0) -> 0 | M41: =IFERROR($J41/100*INDEX(Продукты!$I$6:$I$66,MATCH($E41,Продукты!$A$6:$A$66,0)),0) -> 0 | N41: =IFERROR($J41/100*INDEX(Продукты!$J$6:$J$66,MATCH($E41,Продукты!$A$6:$A$66,0)),0) -> 0 | O41: =IFERROR(IF(IFERROR(INDEX(Рецепты!$H$6:$H$85,MATCH(Меню!$D$7,Рецепты!$H$6:$H$85,0)+10)=Меню!$D$7,FALSE),INDEX(Рецепты!$N$6:$N$85,MATCH(Меню!$D$7,Рецепты!$H$6:$H$85,0)+10),""),"")
A42: =IF($E42="","",Меню!$A$7) | B42: =IF($E42="","",Меню!$B$7) | C42: =IF($E42="","",Меню!$C$7) | D42: =IF($E42="","",Меню!$D$7) | E42: =IFERROR(IF(IFERROR(INDEX(Рецепты!$H$6:$H$85,MATCH(Меню!$D$7,Рецепты!$H$6:$H$85,0)+11)=Меню!$D$7,FALSE),INDEX(Рецепты!$J$6:$J$85,MATCH(Меню!$D$7,Рецепты!$H$6:$H$85,0)+11),""),"") | F42: =IF($E42="","",INDEX(Рецепты!$K$6:$K$85,MATCH(Меню!$D$7,Рецепты!$H$6:$H$85,0)+11)) | G42: =IF($E42="","",INDEX(Рецепты!$M$6:$M$85,MATCH(Меню!$D$7,Рецепты!$H$6:$H$85,0)+11)) | H42: =IFERROR(IF(IFERROR(INDEX(Рецепты!$H$6:$H$85,MATCH(Меню!$D$7,Рецепты!$H$6:$H$85,0)+11)=Меню!$D$7,FALSE),INDEX(Рецепты!$L$6:$L$85,MATCH(Меню!$D$7,Рецепты!$H$6:$H$85,0)+11),0),0) -> 0 | I42: =IF($F42="","",Меню!$E$7) | J42: =IFERROR($H42*$I42,0) -> 0 | K42: =IFERROR($J42/100*INDEX(Продукты!$G$6:$G$66,MATCH($E42,Продукты!$A$6:$A$66,0)),0) -> 0 | L42: =IFERROR($J42/100*INDEX(Продукты!$H$6:$H$66,MATCH($E42,Продукты!$A$6:$A$66,0)),0) -> 0 | M42: =IFERROR($J42/100*INDEX(Продукты!$I$6:$I$66,MATCH($E42,Продукты!$A$6:$A$66,0)),0) -> 0 | N42: =IFERROR($J42/100*INDEX(Продукты!$J$6:$J$66,MATCH($E42,Продукты!$A$6:$A$66,0)),0) -> 0 | O42: =IFERROR(IF(IFERROR(INDEX(Рецепты!$H$6:$H$85,MATCH(Меню!$D$7,Рецепты!$H$6:$H$85,0)+11)=Меню!$D$7,FALSE),INDEX(Рецепты!$N$6:$N$85,MATCH(Меню!$D$7,Рецепты!$H$6:$H$85,0)+11),""),"")
...

Sheet Раскладка
A1: 6. Раскладка для закупки
A3: Итог по названиям продуктов. Резерв и округление до упаковок применяются только здесь. Вода отображается, но по умолчанию исключена из закупочной стоимости.
A5: Продукт_ID | B5: Продукт | C5: Базовая ед. | D5: Нужно всего | E5: Резерв | F5: Купить | G5: Ед. закупки | H5: Размер упаковки | I5: Упаковок | J5: Цена/уп. | K5: Стоимость | L5: В закупку? | M5: Примечание
A6: =Продукты!A6 -> 1 | B6: =Продукты!C6 -> Овсяные хлопья | C6: =Продукты!F6 -> г | D6: =SUMIF(Калькуляция!$E$6:$E$630,$A6,Калькуляция!$J$6:$J$630) -> 0 | E6: =$D6*Ввод!$B$6 -> 0 | F6: =IF($L6="Да",ROUNDUP(($D6+$E6)/$H6,0)*$H6,0) -> 0 | G6: =Продукты!D6 -> пачка | H6: =Продукты!E6 -> 500 | I6: =IFERROR(ROUNDUP(($D6+$E6)/$H6,0),0) -> 0 | J6: =Продукты!K6 -> 650 | K6: =$I6*$J6 -> 0 | L6: =Продукты!L6 -> Да | M6: =Продукты!M6 -> Завтрак
A7: =Продукты!A7 -> 0 | B7: =Продукты!C7 -> 0 | C7: =Продукты!F7 -> 0 | D7: =SUMIF(Калькуляция!$E$6:$E$630,$A7,Калькуляция!$J$6:$J$630) -> 0 | E7: =$D7*Ввод!$B$6 -> 0 | F7: =IF($L7="Да",ROUNDUP(($D7+$E7)/$H7,0)*$H7,0) -> 0 | G7: =Продукты!D7 -> 0 | H7: =Продукты!E7 -> 0 | I7: =IFERROR(ROUNDUP(($D7+$E7)/$H7,0),0) -> 0 | J7: =Продукты!K7 -> 0 | K7: =$I7*$J7 -> 0 | L7: =Продукты!L7 -> 0 | M7: =Продукты!M7 -> 0
A8: =Продукты!A8 -> 0 | B8: =Продукты!C8 -> 0 | C8: =Продукты!F8 -> 0 | D8: =SUMIF(Калькуляция!$E$6:$E$630,$A8,Калькуляция!$J$6:$J$630) -> 0 | E8: =$D8*Ввод!$B$6 -> 0 | F8: =IF($L8="Да",ROUNDUP(($D8+$E8)/$H8,0)*$H8,0) -> 0 | G8: =Продукты!D8 -> 0 | H8: =Продукты!E8 -> 0 | I8: =IFERROR(ROUNDUP(($D8+$E8)/$H8,0),0) -> 0 | J8: =Продукты!K8 -> 0 | K8: =$I8*$J8 -> 0 | L8: =Продукты!L8 -> 0 | M8: =Продукты!M8 -> 0
A9: =Продукты!A9 -> 0 | B9: =Продукты!C9 -> 0 | C9: =Продукты!F9 -> 0 | D9: =SUMIF(Калькуляция!$E$6:$E$630,$A9,Калькуляция!$J$6:$J$630) -> 0 | E9: =$D9*Ввод!$B$6 -> 0 | F9: =IF($L9="Да",ROUNDUP(($D9+$E9)/$H9,0)*$H9,0) -> 0 | G9: =Продукты!D9 -> 0 | H9: =Продукты!E9 -> 0 | I9: =IFERROR(ROUNDUP(($D9+$E9)/$H9,0),0) -> 0 | J9: =Продукты!K9 -> 0 | K9: =$I9*$J9 -> 0 | L9: =Продукты!L9 -> 0 | M9: =Продукты!M9 -> 0
A10: =Продукты!A10 -> 0 | B10: =Продукты!C10 -> 0 | C10: =Продукты!F10 -> 0 | D10: =SUMIF(Калькуляция!$E$6:$E$630,$A10,Калькуляция!$J$6:$J$630) -> 0 | E10: =$D10*Ввод!$B$6 -> 0 | F10: =IF($L10="Да",ROUNDUP(($D10+$E10)/$H10,0)*$H10,0) -> 0 | G10: =Продукты!D10 -> 0 | H10: =Продукты!E10 -> 0 | I10: =IFERROR(ROUNDUP(($D10+$E10)/$H10,0),0) -> 0 | J10: =Продукты!K10 -> 0 | K10: =$I10*$J10 -> 0 | L10: =Продукты!L10 -> 0 | M10: =Продукты!M10 -> 0
A11: =Продукты!A11 -> 0 | B11: =Продукты!C11 -> 0 | C11: =Продукты!F11 -> 0 | D11: =SUMIF(Калькуляция!$E$6:$E$630,$A11,Калькуляция!$J$6:$J$630) -> 0 | E11: =$D11*Ввод!$B$6 -> 0 | F11: =IF($L11="Да",ROUNDUP(($D11+$E11)/$H11,0)*$H11,0) -> 0 | G11: =Продукты!D11 -> 0 | H11: =Продукты!E11 -> 0 | I11: =IFERROR(ROUNDUP(($D11+$E11)/$H11,0),0) -> 0 | J11: =Продукты!K11 -> 0 | K11: =$I11*$J11 -> 0 | L11: =Продукты!L11 -> 0 | M11: =Продукты!M11 -> 0
A12: =Продукты!A12 -> 0 | B12: =Продукты!C12 -> 0 | C12: =Продукты!F12 -> 0 | D12: =SUMIF(Калькуляция!$E$6:$E$630,$A12,Калькуляция!$J$6:$J$630) -> 0 | E12: =$D12*Ввод!$B$6 -> 0 | F12: =IF($L12="Да",ROUNDUP(($D12+$E12)/$H12,0)*$H12,0) -> 0 | G12: =Продукты!D12 -> 0 | H12: =Продукты!E12 -> 0 | I12: =IFERROR(ROUNDUP(($D12+$E12)/$H12,0),0) -> 0 | J12: =Продукты!K12 -> 0 | K12: =$I12*$J12 -> 0 | L12: =Продукты!L12 -> 0 | M12: =Продукты!M12 -> 0
A13: =Продукты!A13 -> 0 | B13: =Продукты!C13 -> 0 | C13: =Продукты!F13 -> 0 | D13: =SUMIF(Калькуляция!$E$6:$E$630,$A13,Калькуляция!$J$6:$J$630) -> 0 | E13: =$D13*Ввод!$B$6 -> 0 | F13: =IF($L13="Да",ROUNDUP(($D13+$E13)/$H13,0)*$H13,0) -> 0 | G13: =Продукты!D13 -> 0 | H13: =Продукты!E13 -> 0 | I13: =IFERROR(ROUNDUP(($D13+$E13)/$H13,0),0) -> 0 | J13: =Продукты!K13 -> 0 | K13: =$I13*$J13 -> 0 | L13: =Продукты!L13 -> 0 | M13: =Продукты!M13 -> 0
A14: =Продукты!A14 -> 0 | B14: =Продукты!C14 -> 0 | C14: =Продукты!F14 -> 0 | D14: =SUMIF(Калькуляция!$E$6:$E$630,$A14,Калькуляция!$J$6:$J$630) -> 0 | E14: =$D14*Ввод!$B$6 -> 0 | F14: =IF($L14="Да",ROUNDUP(($D14+$E14)/$H14,0)*$H14,0) -> 0 | G14: =Продукты!D14 -> 0 | H14: =Продукты!E14 -> 0 | I14: =IFERROR(ROUNDUP(($D14+$E14)/$H14,0),0) -> 0 | J14: =Продукты!K14 -> 0 | K14: =$I14*$J14 -> 0 | L14: =Продукты!L14 -> 0 | M14: =Продукты!M14 -> 0
A15: =Продукты!A15 -> 0 | B15: =Продукты!C15 -> 0 | C15: =Продукты!F15 -> 0 | D15: =SUMIF(Калькуляция!$E$6:$E$630,$A15,Калькуляция!$J$6:$J$630) -> 0 | E15: =$D15*Ввод!$B$6 -> 0 | F15: =IF($L15="Да",ROUNDUP(($D15+$E15)/$H15,0)*$H15,0) -> 0 | G15: =Продукты!D15 -> 0 | H15: =Продукты!E15 -> 0 | I15: =IFERROR(ROUNDUP(($D15+$E15)/$H15,0),0) -> 0 | J15: =Продукты!K15 -> 0 | K15: =$I15*$J15 -> 0 | L15: =Продукты!L15 -> 0 | M15: =Продукты!M15 -> 0
A16: =Продукты!A16 -> 0 | B16: =Продукты!C16 -> 0 | C16: =Продукты!F16 -> 0 | D16: =SUMIF(Калькуляция!$E$6:$E$630,$A16,Калькуляция!$J$6:$J$630) -> 0 | E16: =$D16*Ввод!$B$6 -> 0 | F16: =IF($L16="Да",ROUNDUP(($D16+$E16)/$H16,0)*$H16,0) -> 0 | G16: =Продукты!D16 -> 0 | H16: =Продукты!E16 -> 0 | I16: =IFERROR(ROUNDUP(($D16+$E16)/$H16,0),0) -> 0 | J16: =Продукты!K16 -> 0 | K16: =$I16*$J16 -> 0 | L16: =Продукты!L16 -> 0 | M16: =Продукты!M16 -> 0
A17: =Продукты!A17 -> 0 | B17: =Продукты!C17 -> 0 | C17: =Продукты!F17 -> 0 | D17: =SUMIF(Калькуляция!$E$6:$E$630,$A17,Калькуляция!$J$6:$J$630) -> 0 | E17: =$D17*Ввод!$B$6 -> 0 | F17: =IF($L17="Да",ROUNDUP(($D17+$E17)/$H17,0)*$H17,0) -> 0 | G17: =Продукты!D17 -> 0 | H17: =Продукты!E17 -> 0 | I17: =IFERROR(ROUNDUP(($D17+$E17)/$H17,0),0) -> 0 | J17: =Продукты!K17 -> 0 | K17: =$I17*$J17 -> 0 | L17: =Продукты!L17 -> 0 | M17: =Продукты!M17 -> 0
